Workbook

Sheet 表格说明
A1: 中国银保监会银行业金融机构监管数据标准化规范 数据结构一览表说明
A2: 1. 标准化数据结构以表形式组织。一个或多个表归属于一个分类，每个表包含多个数据项。
A3: 2. 数据项已按表进行分类组合，通过使用最左侧导航按钮，可以展开或隐藏各表数据项，便于查看。
A4: 3. 数据结构备注中PK为监管部门作为唯一性约束的参考条件，含有多个PK的，表示联合主键的参考，并不作为主外键唯一性约束的要求，银行机构可根据数据实际入库情况作出调整。
A5: 4. “数据元说明”定义数据项的类型及长度的表示形式。
A6: 5. 数据项中备注“关联数据项：[表名].[数据项名]”表示该数据项取值的参考数据项。例如“关联数据项:机构信息表.内部机构号”表示该数据项应和“机构信息表”中的“内部机构号”数据项取值一致。
A7: 6. Cn 表示n个字节的固定长度，相应的字符长度由字符编码集确定。UTF-8的中文字符占3个字节。
A8: 7. C..n 表示最多为n个字节的可变长度。UTF-8的中文字符占3个字节。
A9: 8. I 表示整数可计算形式。
A10: 9. I..n 表示最多为n位的整数可计算形式。
A11: 10. Dw.d 表示十进制小数可计算形式，w表示包含小数点前后字符位在内的整个字段最多字符位数，d表示小数点后的最多字符位数。
A12: 11. F 表示任意长度浮点数。
... A14: 数据治理体系公众号推荐

Sheet 表结构总览
A1: 主题 | B1: 主题编号 | C1: 数据表代码 | D1: 数据表名 | E1: 数据表编号 | F1: 报送模式 | G1: 报送要求 | H1: 修改说明
A2: 公共信息 | B2: 001
C3: JGXXB | D3: 机构信息表 | E3: 101 | F3: 全量表，报送截至采集日有效的数据，以及上一采集日至采集日期间结清、失效、终结等所有视为终态的数据。 | G3: 本表报送银行机构或业务中心信息，业务中心包含管理机构、营业机构、内设机构、虚拟机构。对于营业机构、内设机构、虚拟机构，银行机构代码、金融许可证号等字段可以取上级机构或者本级实体机构对应的信息（优先取本级实体机构）。境外机构也需要报送，根据实际情况无法填报的字段可以为空。子公司不必报送（理财子公司应报送）。内设机构标准：承担业务归属的机构。机构永久关停、撤销等情况的，在报送最后状态的次月可不再报送。 | H3: 修改
C4: YGB | D4: 员工表 | E4: 102 | F4: 全量表，报送截至采集日有效的数据，以及上一采集日至采集日期间结清、失效、终结等所有视为终态的数据。 | G4: 在职类员工需每月报送。员工状态转为离职的，在报送该员工最后状态的次月可不再报送。子公司员工不用报送（理财子公司应报送）。 | H4: 修改
C5: GYB | D5: 柜员表 | E5: 103 | F5: 全量表，报送截至采集日有效的数据，以及上一采集日至采集日期间结清、失效、终结等所有视为终态的数据。 | G5: 包含实体柜员和虚拟柜员。为虚拟柜员时，工号、银行机构代码等字段依业务实际填列（若无则置空），如报送虚拟柜员，则通过“柜员类型”字段进行区分；柜员状态转为注销、无效等时，可在报送该条数据最终状态的次月不再报送。 | H5: 修改
C6: GWXXB | D6: 岗位信息表 | E6: 104 | F6: 全量表，报送截至采集日有效的数据，以及上一采集日至采集日期间结清、失效、终结等所有视为终态的数据。 | G6: 银行机构内设立的所有岗位的相关信息，至少应包括核心和人力资源系统中的所有岗位信息。撤销的岗位于次月不再报送。 | H6: 修改
C7: JGGXB | D7: 机构关系表 | E7: 105 | F7: 全量表，报送截至采集日有效的数据，以及上一采集日至采集日期间结清、失效、终结等所有视为终态的数据。 | G7: 报送范围应包括所有进行账务处理的机构，至少应包括总行、分行、支行等实体机构和省级汇总、地市级汇总、法人汇总、分行汇总。会计全科目表中的机构在机构关系表中都需要报送，每次全量报送。 | H7: 修改
C8: GDJGLFXXB | D8: 股东及关联方信息表 | E8: 106 | F8: 全量表，报送截至采集日有效的数据，以及上一采集日至采集日期间结清、失效、终结等所有视为终态的数据。 | G8: 填报银行股东及银行关联方相关信息。股东：对于已上市银行，需填报持有或控制1%以上股份或表决权，及虽不足1%但对商业银行经营管理有重大影响的股东。未上市银行机构应报送所有的对公、个人股东信息。包括金融产品。 关联方：参照《银行保险机构关联交易管理办法》（中国银行保险监督管理委员会令〔2022〕1号）第二章规定。 | H8: 修改
A9: 客户信息 | B9: 002
C10: GRJCXXB | D10: 个人基础信息表 | E10: 201 | F10: 全量表，报送截至采集日有效的数据，以及上一采集日至采集日期间结清、失效、终结等所有视为终态的数据。 | G10: 报送范围包括本行客户及本行客户的担保、配偶、亲属关系所涉及到的个人信息。包括核心系统、客户关系系统、信用卡系统等各类信息系统采集的个人客户信息。 | H10: 修改
C11: GRKHGXB | D11: 个人客户关系表 | E11: 202 | F11: 全量表，报送截至采集日有效的数据，以及上一采集日至采集日期间结清、失效、终结等所有视为终态的数据。 | G11: 个人客户的所有关联关系，包括个人对个人、个人对对公的相关关联关系。本人为本人担保的关系不报送。 | H11: 修改
C12: DGKHXXB | D12: 对公客户信息表 | E12: 203 | F12: 全量表，报送截至采集日有效的数据，以及上一采集日至采集日期间结清、失效、终结等所有视为终态的数据。 | G12: 银行机构所有对公客户的基本信息。集团类的虚拟客户的客户信息要上报。银行对企业分公司等非法人机构授信的，视同单一法人客户报送。以机构名义登记客户资料的个体工商户、私营业主应纳入本表填报范围。对于同业客户、政府机关、境外客户，若无法获取相关信息无法填报的数据项，允许为空。对于不再列为银行客户的数据不报送。 | H12: 修改
C13: DGKHCWXXB | D13: 对公客户财务信息表 | E13: 204 | F13: 增量表，报送上一采集日至采集日期间新增的数据。 | G13: 报送本月源系统中新收集的对公客户财务信息。对于非授信客户、负债类客户、离岸对公客户、机关事业单位、未达到税务部门建账标准的个体工商户等无需报送。 | H13: 新增
C14: JTKHB | D14: 集团客户表 | E14: 205 | F14: 全量表，报送截至采集日有效的数据，以及上一采集日至采集日期间结清、失效、终结等所有视为终态的数据。 | G14: 报送在本行纳入集团授信的客户信息，包括供应链客户信息。以集团成员为最小粒度报送。同业集团客户信息无需报送。 | H14: 新增
C15: GLGXB | D15: 关联关系表 | E15: 206 | F15: 全量表，报送截至采集日有效的数据，以及上一采集日至采集日期间结清、失效、终结等所有视为终态的数据。 | G15: 报送机构收集的对公客户以及机构互联网贷款合作方的关联关系。应包括母公司，子公司，与该企业受同一母公司控制的其他企业，与该企业实施共同控制的投资方，对该企业施加重大影响的投资方，该企业的合营企业，该企业的联营企业，该企业的主要投资者个人及与其关系密切的家庭成员，该企业或其母公司的关键管理人员及与其关系密切的家庭成员，该企业主要投资者个人、关键管理人员或与其关系密切的家庭成员控制、共同控制或施加重大影响的其他企业，供应链上下游，担保关系等。应采取能采尽采的原则，包括但不限于授信尽职调查、外部数据源查询等途径获知的关联关系。同一关联方兼任或具有多重关联关系的，分多条进行报送。 | H15: 修改
A16: 卡片信息 | B16: 003
C17: JJKXXB | D17: 借记卡信息表 | E17: 301 | F17: 全量表，报送截至采集日有效的数据，以及上一采集日至采集日期间结清、失效、终结等所有视为终态的数据。 | G17: 个人和对公客户在银行机构开办的借记卡信息，指只能存取款而无法透支的卡片信息。当卡片状态为“注销”时，可在报送最后状态的次月不再报送。 | H17: 修改
C18: CZXXB | D18: 存折信息表 | E18: 302 | F18: 全量表，报送截至采集日有效的数据，以及上一采集日至采集日期间结清、失效、终结等所有视为终态的数据。 | G18: 个人和对公客户在银行机构开办的存折信息，包括存折和存单。当存折状态为“注销”时，可在报送最后状态的次月不再报送。 | H18: 修改
C19: SDSHXXB | D19: 收单商户信息表 | E19: 303 | F19: 全量表，报送截至采集日有效的数据，以及上一采集日至采集日期间结清、失效、终结等所有视为终态的数据。 | G19: 报送本行因线下线上收单业务而拓展的线下POS终端、线上终端以及二维码商户的信息。同一商户存在多个POS终端的，按多条报送。商户状态为“失效”或“注销”等状态的，在报送最后状态的次月可不再报送。 | H19: 新增
A20: 会计记账信息 | B20: 004
C21: ZZKJQKMB | D21: 总账会计全科目表 | E21: 401 | F21: 全量表，报送截至采集日有效的数据，以及上一采集日至采集日期间结清、失效、终结等所有视为终态的数据。 | G21: 本表报送银行机构会计记账使用的有余额的或余额变动的会计科目。只报境内银行（不报子公司），包括总行、一级分行、二级分行、一级支行（最多报4级）。如果发生新老科目变更，在当期数据中报送最新科目即可。每月最后一天数据应同时报送按月和按日为周期的会计数据，每年最后一天数据应同时报送按日、按月、季、半年、年为周期的会计数据，以此类推。只报送人民币和本外币合计。 | H21: 修改
C22: NBKMDZB | D22: 内部科目对照表 | E22: 402 | F22: 全量表，报送截至采集日有效的数据，以及上一采集日至采集日期间结清、失效、终结等所有视为终态的数据。 | G22: 本表报送总账会计全科目的上下级对应关系，以会计科目为最小粒度报送。内部科目对照表由法人机构统一确定，分支机构按同一内容报送。报送科目必须与当期《总账会计全科目表》中的科目一致。此表首次采集为全量采集，后续采集如有变化，需全量报送。 | H22: 修改
C23: GRCKFHZ | D23: 个人存款分户账 | E23: 403 | F23: 全量表，报送截至采集日有效的数据，以及上一采集日至采集日期间结清、失效、终结等所有视为终态的数据。 | G23: 填报个人存款账户信息，个人存款账户和对公存款账户按照《人民币银行结算账户管理办法》（中国人民银行令2003年第5号）划分。信用卡业务不在本表中填报。个体工商户、私营业主以个人名义开立的存款账户计入本表，以营业执照等证件开立的对公账户不计入本表。以存款账号为最小粒度报送，如账户注销或终结，在报送该账户最终状态后的次月可不再报送。 | H23: 修改
C24: GRCKFHZMX | D24: 个人存款分户账明细记录 | E24: 404 | F24: 增量表，报送上一采集日至采集日期间新增的数据。 | G24: 除计息、扣利息税外，所有影响个人存款账户余额变动的交易信息，包括结息交易，不包括查询交易。 | H24: 修改
C25: DGCKFHZ | D25: 对公存款分户账 | E25: 405 | F25: 全量表，报送截至采集日有效的数据，以及上一采集日至采集日期间结清、失效、终结等所有视为终态的数据。 | G25: 填报银行机构吸收的除个人以外的机构（包括企业、财政部门、社保基金、部队、住房公积金、社会团体、同业机构等）开立的所有存款账户信息。个人存款账户和对公存款账户按照《人民币银行结算账户管理办法》（中国人民银行令2003年第5号）划分。个体工商户、私营业主以营业执照等证件开立的对公账户计入本表，以个人名义开立的账户不计入本表。以存款账号为最小颗粒报送，如账户注销或终结，在报送该账户最终状态后的次月可不再报送。 | H25: 修改
C26: DGCKFHZMX | D26: 对公存款分户账明细记录 | E26: 406 | F26: 增量表，报送上一采集日至采集日期间新增的数据。 | G26: 除计息、扣利息税外，所有影响对公存款账户余额变动的交易信息，包括结息交易，不包括查询交易。 | H26: 修改
C27: NBFHZ | D27: 内部分户账 | E27: 407 | F27: 全量表，报送截至采集日有效的数据，以及上一采集日至采集日期间结清、失效、终结等所有视为终态的数据。 | G27: 根据会计核算科目，除单列账之外的科目原则上都归入内部账采集；单列账报送至信用卡、对公/个人等分户账中；资本账户需要报送。以内部分户账号为最小颗粒报送，如账户注销或终结，在报送该账户最终状态后的次月可不再报送。交易与核算分离的机构，应根据总账科目中划分出对应内部分户账性质的科目，自定义内部分户账号进行报送。 | H27: 修改
C28: NBFHZMX | D28: 内部分户账明细记录 | E28: 408 | F28: 增量表，报送上一采集日至采集日期间新增的数据。 | G28: 根据会计核算科目，除单列账之外的科目原则上都归入内部账采集；单列账报送至信用卡、对公/个人等分户账中；资本账户需要报送。 | H28: 修改
C29: GRXDFHZ | D29: 个人信贷分户账 | E29: 409 | F29: 全量表，报送截至采集日有效的数据，以及上一采集日至采集日期间结清、失效、终结等所有视为终态的数据。 | G29: 填报以个人名义在银行机构所开立的信贷账户信息。不报送信用卡业务。表外业务只报送委托贷款（非现金管理项下），其他不报送。个体工商户、私营业主以个人名义开立的信贷分户账计入本表，以营业执照等证件开立的对公信贷分户账不计入本表。以信贷借据号为最小粒度报送，借据结清、核销或转让的，可在报送最后状态的次月不再报送。账户状态为“销户”时，也可于次月不再报送。 | H29: 修改
C30: GRXDFHZMX | D30: 个人信贷分户账明细记录 | E30: 410 | F30: 增量表，报送上一采集日至采集日期间新增的数据。 | G30: 所有影响个人信贷账户余额或利息变动的交易信息，包括还本、还息，不包括查询交易。贷款核销或者转让（包括资产证券化）也应该在本表体现：明细科目填报本金科目，交易金额为核销或转让前本金余额，余额填报为0，交易对手填写借款人自身信息，摘要中标明核销或者转让交易。 | H30: 修改
C31: DGXDFHZ | D31: 对公信贷分户账 | E31: 411 | F31: 全量表，报送截至采集日有效的数据，以及上一采集日至采集日期间结清、失效、终结等所有视为终态的数据。 | G31: 除个人以外的各类机构（包括企业、机关团体、社保基金、部队、住房公积金）为开展各项信贷业务，在银行机构所开立的信贷账户信息。个体工商户、私营业主以营业执照等证件开立的对公信贷分户账计入本表，以个人名义开立的信贷分户账不计入本表。贷款核销和转让（包括资产证券化）相关内容应在本表填报；尤其核算方式变化（即科目变化），需要报送变化量。表外业务只报送委托贷款（非现金管理项下），其他不报送。对于票据贴现和买断式转贴现，可以填报为信贷分户账号=信贷借据号=票据号码；对于其他若没有对应信贷分户账号的业务，可以填报为信贷分户账号=信贷借据号=业务编号。以信贷借据号为最小粒度报送，借据结清、核销或转让的，可在报送最后状态的次月不再报送。账户状态为“销户”时，也可于次月不再报送。 | H31: 修改
C32: DGXDFHZMX | D32: 对公信贷分户账明细记录 | E32: 412 | F32: 增量表，报送上一采集日至采集日期间新增的数据。 | G32: 所有影响对公信贷账户余额或利息变动的交易信息，包括还本、还息，不包括查询交易。贷款核销或者转让（包括资产证券化）也应该在本表体现：明细科目填报本金科目，交易金额为核销或转让前本金余额，余额填报为0，交易对手填写借款人自身信息，摘要中标明核销或者转让交易。 | H32: 修改
A33: 各项贷款 | B33: 005
C34: XDHTB | D34: 信贷合同表 | E34: 501 | F34: 全量表，报送截至采集日有效的数据，以及上一采集日至采集日期间结清、失效、终结等所有视为终态的数据。 | G34: 报送范围应至少包括1104报表中：各项贷款+非现金管理项下委托贷款-信用卡。如，个人贷款、对公贷款、票据贴现、买断式转贴现、贸易融资业务、融资租赁业务、委托贷款（非现金管理项下）对应的业务合同，以及各项垫款对应的原业务合同。表外业务只报送委托贷款（非现金管理项下），其他不报送。信用卡业务不报送。对于票据贴现和买断式转贴现，可以填报为信贷合同号=信贷借据号=票据号码；对于其他若没有对应合同号的业务，可以填报为信贷合同号=信贷借据号=业务编号。已撤销、失效、终结的合同在报送合同最后状态的次月可不再报送。 | H34: 修改 | J34: 报送范围应至少包括1104中：各项贷款+非现金管理项下的委托贷款-信用卡。如，个人贷款、对公贷款、票据贴现、买断式转贴现、贸易融资业务、融资租赁业务、委托贷款（非现金管理项下）对应的业务合同，以及各项垫款对应的原业务合同。委托贷款中现金管理项下委托贷款不报送，其他表外业务不报送。信用卡业务不报送。对于票据贴现和买断式转贴现，可以填报为信贷合同号=信贷借据号=票据号码；对于其他若没有对应合同号的业务，可以填报为信贷合同号=信贷借据号=业务编号。已撤销、失效、终结的合同在报送合同最后状态的次月可不再报送。
C35: HLWDKHTFJB | D35: 互联网贷款合同附加表 | E35: 502 | F35: 全量表，报送截至采集日有效的数据，以及上一采集日至采集日期间结清、失效、终结等所有视为终态的数据。 | G35: 本表报送所有互联网贷款合同的附加信息。互联网贷款的认定参照《商业银行互联网贷款管理暂行办法》。互联网贷款的发放明细应该报送至相对应的信贷业务借据表、信贷合同表、信贷分户账以及信贷分户账明细记录中。已撤销、失效、终结的合同在报送合同最后状态的次月可不再报送。 | H35: 新增
C36: GRXDYWJJB | D36: 个人信贷业务借据表 | E36: 503 | F36: 全量表，报送截至采集日有效的数据，以及上一采集日至采集日期间结清、失效、终结等所有视为终态的数据。 | G36: 所有以个人名义在信贷业务中签订的借据信息。个体工商户、私营业主以个人名义办理的贷款的计入本表，以机构名义办理的贷款不计入本表。表外业务只报送委托贷款（非现金管理项下），其他不报送。信用卡业务不报送。对于票据贴现和买断式转贴现，可以填报为信贷合同号=信贷借据号=票据号码；对于其他若没有对应借据号的业务，可以填报为信贷合同号=信贷借据号=业务编号。借据状态为结清、核销、转让的可在报送最后状态的次月不再报送。 | H36: 修改
C37: DGXDYWJJB | D37: 对公信贷业务借据表 | E37: 504 | F37: 全量表，报送截至采集日有效的数据，以及上一采集日至采集日期间结清、失效、终结等所有视为终态的数据。 | G37: 所有以机构名义在信贷业务中签订的借据信息。个体工商户、私营业主以机构名义办理的贷款计入本表，以个人名义办理的贷款不计入本表。表外业务只报送委托贷款（非现金管理项下），其他不报送。信用卡业务不报送。对于票据贴现和买断式转贴现，可以填报为信贷合同号=信贷借据号=票据号码；对于其他若没有对应借据号的业务，可以填报为信贷合同号=信贷借据号=业务编号。转贴、二级市场福费廷业务的借款人按照交易对手（同业）填报，贴现和信用证下融资的借款人按照贴现申请人、信用证融资人填报。借据状态为结清、核销、转让的可在报送最后状态的次月不再报送。 | H37: 修改
C38: STZFXXB | D38: 受托支付信息表 | E38: 505 | F38: 增量表，报送上一采集日至采集日期间新增的数据。 | G38: 《个人信贷业务借据表》和《对公信贷业务借据表》中放款方式为“受托支付”或“混合支付”的，在该表中报送受托支付对象信息。 | H38: 新增
C39: XMDKXXB | D39: 项目贷款信息表 | E39: 506 | F39: 全量表，报送截至采集日有效的数据，以及上一采集日至采集日期间结清、失效、终结等所有视为终态的数据。 | G39: 符合以下特征的贷款的相关信息：（一）贷款用途通常是用于建造一个或一组大型生产装置、基础设施、房地产项目或其他项目，包括对在建或已建项目的再融资；（二）借款人通常是为建设、经营该项目或为该项目融资而专门组建的企事业法人，包括主要从事该项目建设、经营或融资的既有企事业法人；（三）还款资金来源主要依赖该项目产生的销售收入、补贴收入或其他收入，一般不具备其他还款来源。以信贷借据号为最小颗粒报送，同一合同下多笔借据的按多条报送。已结清、核销的数据在次月不再报送。 | H39: 修改
C40: YTDKXXB | D40: 银团贷款信息表 | E40: 507 | F40: 全量表，报送截至采集日有效的数据，以及上一采集日至采集日期间结清、失效、终结等所有视为终态的数据。 | G40: 银（社）团贷款信息。以信贷借据号为最小颗粒报送，同一合同下多笔借据的按多条报送。已结清、核销的数据在次月不再报送。 | H40: 修改
...

Sheet 数据元说明
A2: 数据元说明
A4: 分类 | B4: 数据元编码 | C4: 数据元名称 | D4: 数据元英文 | E4: 数据元说明 | F4: 格式
A6: 公共信息 | B6: 001
B7: 001001 | C7: 名称 | D7: Name | E7: 名称应与公章所使用的名称完全一致。银行机构以银保监会金融机构许可证登记名称为准。无独立金融机构许可证的机构，可在本名称中体现出机构特征。第三方支付平台填报第三方支付平台名称。 客户名称按照客户的不同类型按如下标准填报。 （1）集团客户，填报银行对该集团授信采用的集团客户名称。视同集团客户填报的供应链融资填报核心企业客户名称。 （2）单一法人客户，经有关部门批准正式使用的全称，与公章所使用的名称完全一致。视同单一法人客户填报的分公司，填报分公司全称，与分公司公章所使用的名称完全一致。客户是境内涉密机构的，客户名称填报为“*********”。 （3）同业客户，经有关部门批准正式使用的客户全称，与客户公章所使用的名称完全一致。 （4）自然人，与有效证件上的姓名一致。 （5）境外客户，客户名称填报英文名称。 | F7: C..450
B8: 001002 | C8: 是否标志 | D8: Yes or No | E8: 是，否。 | F8: C3
B9: 001003 | C9: 比例 | D9: Ratio | E9: 百分比为单位，即1/100，保留两位小数。如4.5%则填报为4.50。 | F9: D20.2
B10: 001004 | C10: 比例（精） | D10: Accurate rate | E10: 百分比为单位，即1/100，保留六位小数。4.123456%则填报为4.123456。 | F10: D20.6
B11: 001005 | C11: 日期 | D11: Date | E11: YYYYMMDD，默认值99991231。 | F11: C8
B12: 001006 | C12: 年月 | D12: Year & Month | E12: YYYYMM，默认值999912。 | F12: C6
B13: 001007 | C13: 时间 | D13: Time | E13: 24小时制时间，精确到秒。hhmmss，默认值000000。 | F13: C6
B14: 001008 | C14: 地址 | D14: Address | E14: 中文描述。个人填报个人住址。机构填报有关部门批准的有效证件上登记的地址。参照《企业法人营业执照》中的注册地填报，要写明省（区、市）、地（区、市、州、盟）、县（区、市、旗）。境内涉密机构不填报。客户为境外企业的，填报客户在境外的注册地址（英文）。 | F14: C..600
B15: 001009 | C15: 电话 | D15: Tel. | E15: 手机号码或者区号-固定电话号码。 | F15: C..30
B16: 001010 | C16: 银行机构代码 | D16: Bank code | E16: 12位人行支付行号或SWIFT行号。 | F16: C..30
B17: 001011 | C17: 金融许可证号 | D17: Financial license number | E17: 金融许可证机构编码编制规则（试行） 一、机构编码结构 机构编码由大写英文字母和数字组成，共15位。分六个部分，分别是机构类型代码、机构代码、组织类别代码、发证机关代码、地址代码、顺序代码，从左至右顺序排列，如下表所示。 二、机构编码含义 （一）第［一］位是机构类型代码，用大写英文字母表示。 A-政策性银行 B-商业银行 C-农村合作银行 D-城市信用社 E-农村信用社 F-资金互助社 J-金融资产管理公司 K-信托公司 L-财务公司 M-金融租赁公司 N-汽车金融公司 P-货币经纪公司 Q-贷款公司 Z-其他类金融机构 新增机构类型时，根据需要确定机构类型代码。 （二）第［二］位至第［五］位是机构代码，用数字表示。 1.每个法人机构指定唯一的代码，由计算机系统按照规则自动生成。除农村信用社、资金互助社、贷款公司（E、F、Q类机构）外，全国统一编码。E、F、Q类机构在省（自治区、直辖市）范围内统一编码。 2.新设立的机构依照所属机构类型顺序排列。 机构代码编码示例如下： A-政策性银行 0001-国家开发银行 …… B-商业银行 0001-中国工商银行股份有限公司 …… C-农村合作银行 0001-天津大港农村合作银行 …… D-城市信用社 0001-邯郸市城市信用社股份有限公司 …… E-农村信用社天津市 0001-天津市宝坻区农村信用合作联社 …… 新疆维吾尔自治区 0001-新疆维吾尔自治区农村信用社联合社 …… F-资金互助社 吉林省 0001-吉林省梨树县闰家村百信农村资金互助社 …… 青海省 0001-青海省乐都县雨润镇兴乐农村资金互助社 …… J-金融资产管理公司 0001-中国华融资产管理公司 …… K-信托投资公司 0001-中诚信托投资有限责任公司 …… L-财务公司 0001-中海石油财务有限责任公司 …… M-金融租赁公司 0001-中国外贸金融租赁公司 …… N-汽车金融公司 0001-大众汽车金融（中国）有限公司 …… P-货币经纪公司 0001-上海国利货币经纪有限公司 …… Q-贷款公司四川省 0001-四川省仪陇县惠民贷款有限责任公司 …… 新疆维吾尔自治区 0001- …… Z-其他类金融机构 0001-中央国债登记结算有限责任公司 …… （三）第〔六〕位是组织类别代码，用大写英文字母表示。 机构类型不同，组织类别代码的含义不同。定义如下： 1.A-政策性银行 H-总行 G-总行营业部 H-级分行 K-一级分行营业部 M-二级分行 S-支行 X-其他分支机构 2.B-商业银行 H-总行 G-总行营业部、专营机构 B-一级分行 K-一级分行营业部 L-二级分行 M-直属支行 N-二级分行营业部 S-支行 U-分理处、办事处、营业所 V-储蓄所 X-其他分支机构 3.C-农村合作银行 H-总行 S-支行 U-分理处 V-储蓄所 X-其他分支机构 4.D-城市信用社 H-法人 S-分社、营业部 X-其他分支机构 5.E-农村信用社 H-省（自治区、直辖市）联合社 B-地（市）联合社、联社 S-县（市）联合社、联社、合作社（县级） T-信用合作社 U-信用社、分社 V-储蓄所 X-其他分支机构 6.F-资金互助社 H-法人 7.J-金融资产管理公司 H-总公司 B-办事处 X-其他分支机构 8.K-信托公司 H-法人 9.N-汽车金融公司 H-法人 10.L-财务公司 H-总公司 B-分公司 X-其他分支机构 11.M-金融租赁公司 H-总公司 B-分公司 X-其他分支机构 12.P-货币经纪公司 H-总公司 B-分公司 X-其他分支机构 13.Q-贷款公司 H-总公司 B-分公司 X-其他分支机构 14.Z-其他类金融机构 Z类机构组织类别代码编码方法参照以上规则。 新增机构类型时，参照以上规则，根据实际情况定义其组织类别代码。 （四）第〔七〕位是发证机关代码，用数字表示。 1-银保监会 2-银监局 3-银监分局 （五）第〔八〕位至第〔十一〕是地址代码，用数字表示。按照《中华人民共和国行政区划代码》 （GB/T2260），取市（地区、自治州、盟）、直辖市行政区划代码前四位，作为地址代码。 地址代码示例如下：1100表示北京市，1200表示天津市，1301表示石家庄市，…… （六）第〔十二〕位至第〔十五〕位是顺序代码，用数字表示。机构类型代码、机构代码、组织类别代码、发证机关代码和地址代码相同的机构按照制发金融许可证的顺序编码。 三、机构编码的编制规则 编制机构编码时，按照从左至右的顺序依次确定机构类型代码、机构代码、组织类别代码、发证机关代码、地址代码、顺序代码，由计算机自动生成。 为了保证机构编码的唯一性，以利于电子计算机较长时间地存储数据，因行政许可变更需换发金融许可证，涉及机构编码变更的，原机构编码不再使用.金融机构终止的，机构编码不再使用。注销开业许可收回金融许可证的，机构编码不再使用。 | F17: C..30
B18: 001012 | C18: 内部机构号 | D18: Inner organization number | E18: 银行内部机构号。应具有标识机构的唯一性。 | F18: C..30
... B40: 001034 | C40: 员工状态 | D40: State of staff | E40: 在岗，离岗，离职，其他-银行自定义。无法以枚举类型填报的，以“其他-XX”填报，其中“XX”为银行自定义类型。 | F40: C..30
B41: 001035 | C41: 柜员状态 | D41: State of Teller | E41: 在岗，离岗，其他-银行自定义。无法以枚举类型填报的，以“其他-XX”填报，其中“XX”为银行自定义类型。
B42: 001036 | C42: IP地址 | D42: IP address | E42: 点分十进制格式表示的IPV4地址，或者IPV6地址。 | F42: C..40
B43: 001037 | C43: MAC地址 | D43: MAC address | E43: 网络设备唯一的网络标识： 1.可以是MAC地址，以12个16进制数表示（6个字节），每个字节以英文半角冒号（:）隔开。 2.若交易渠道为网银、手机银行，Android7.0以上系统可填报设备IMEI码；IOS7以上系统科填报UUID码，唯一对应设备即可。 | F43: C..60
B44: 001038 | C44: 备注 | D44: Remark | E44: 银行自定义。 | F44: C..600
A45: 客户信息 | B45: 002
B46: 002001 | C46: 客户统一编号 | D46: Customer number | E46: 银行自定义的唯一识别客户的标识。供应链融资的填写供应链融资编码。 | F46: C..60
B47: 002002 | C47: 证件类别 | D47: Document type | E47: 同业客户：银行机构代码，金融许可证号，SWIFT编码，其他-XX。 对公客户：统一社会信用代码，组织机构代码，营业执照（工商注册号），公司注册证书，全球法人识别码，其他-XX。 个人客户：居民身份证，军官证，文职干部证，警官证，士兵证，户口簿，临时身份证，其他有效通行旅行证件，护照，学生证，无证件，其他-XX。 无法以枚举类型填报的，以“其他-XX”报送，其中“XX”为银行自定义类型。 对公客户优先填报统一社会信用代码，没有统一社会信用代码的对公客户填报组织机构代码。组织机构代码、统一社会信用代码均没有的可以填报客户提供的批文文号、开户主证件、上级机构统一社会信用代码等，以“其他-XX”填报。 | F47: C..60
B48: 002003 | C48: 证件号码 | D48: Document number | E48: 与证件类别对应的证件号码。涉及个人身份证件时需按照本规范给定规则进行脱敏处理。 | F48: C..70
B49: 002004 | C49: 国籍 | D49: Nationality | E49: 参照《GB/T 2659-2000 世界各国和地区名称》，填报中文名称。 | F49: C..60
B50: 002005 | C50: 民族 | D50: Ethnicity | E50: 国家认可的在公安户籍管理部门正式登记注册的客户所属民族的名称。 | F50: C..30
B51: 002006 | C51: 性别 | D51: Gender | E51: 男，女。 | F51: C3
B52: 002007 | C52: 学历 | D52: Education degree | E52: 《学历代码》（GB/T 4658）规定的学历。 | F52: C..30
B53: 002008 | C53: 职业 | D53: Career | E53: 中文描述或中文字典，银行自定义。 | F53: C..90
B54: 002009 | C54: 单位性质 | D54: Unit property | E54: 国有企业、民营企业、政府机关、事业单位、社会团体、境外机构、其他-银行自定义。无法以枚举类型填报的，以“其他-XX”填报，其中“XX”为银行自定义类型。 | F54: C..60
B55: 002010 | C55: 社会关系 | D55: Social relationship | E55: 配偶，父母，子女，亲属关系，朋友，同事，合作伙伴，离异原配偶，其他-银行自定义。无法以枚举类型填报的，以“其他-XX”填报，其中“XX”为银行自定义类型。 | F55: C..60
B56: 002011 | C56: 法人代表 | D56: Legal person | E56: 该对公客户法人代表。依照法律或者法人组织章程规定，代表法人行使职权的负责人姓名。 | F56: C..150
B57: 002012 | C57: 营业执照号 | D57: Business license number | E57: 已登记统一社会信用代码的，填18位统一社会信用代码；未登记统一社会信用代码的，填报营业执照注册号。 | F57: C..60
... B73: 002028 | C73: 财务报表编号 | D73: Financial statement number | E73: 唯一标识财务报表的编号，银行自定义。 | F73: C..30
A74: 账户 | B74: 003
B75: 003001 | C75: 账号 | D75: Account number | E75: 系统内最细一级的账号，无唯一性约束，不需要和序号、子序号等做拼接。 | F75: C..60
B76: 003002 | C76: 会计科目编号 | D76: Subject number of general ledger accounting | E76: 机构实际使用的总账会计科目编码。 | F76: C..60
B77: 003003 | C77: 会计科目名称 | D77: Subject name of general ledger accounting | E77: 机构实际使用的总账会计科目编码对应的名称。 | F77: C..300
B78: 003004 | C78: 会计科目级次 | D78: Subject grade of general ledger accounting | E78: 总账会计科目编号在科目结构中所对应的级次。 | F78: I
B79: 003005 | C79: 会计科目大类 | D79: Account category | E79: 资产、负债、所有者权益、损益、资产负债共同类、表外、其他。 | F79: C..30
...

Sheet 数据结构
A2: 中国银保监会银行业金融机构监管数据标准化规范（2021版）
A4: 分类 | B4: 分类编号 | C4: 传输文件名称 | D4: 表名 | E4: 表编号 | F4: 数据项名称 | G4: 数据项编号 | H4: 数据项代码 | I4: 数据元 | J4: 数据元编码 | K4: 数据元说明 | L4: 格式 | M4: 备注 | N4: 变更类型 | O4: 变更规范列 | P4: 变更说明
A6: 公共信息 | B6: 001 | F6: 数据治理体系公众号推荐
C7: JGXXB | D7: 机构信息表 | E7: 101 | M7: =INDEX(表结构总览!D:G,MATCH(D7,表结构总览!D:D,0),4) -> 本表报送银行机构或业务中心信息，业务中心包含管理机构、营业机构、内设机构、虚拟机构。对于营业机构、内设机构、虚拟机构，银行机构代码、金融许可证号等字段可以取上级机构或者本级实体机构对应的信息（优先取本级实体机构）。境外机构也需要报送，根据实际情况无法填报的字段可以为空。子公司不必报送（理财子公司应报送）。内设机构标准：承担业务归属的机构。机构永久关停、撤销等情况的，在报送最后状态的次月可不再报送。 | N7: 修改 | O7: 备注
C8: JGXXB | D8: 机构信息表 | E8: 101 | F8: 银行机构代码 | G8: 10101 | H8: YHJGDM | I8: 银行机构代码 | J8: =INDEX(数据元说明!A:F,MATCH(I8,数据元说明!C:C,0),2) -> 001010 | K8: =INDEX(数据元说明!A:F,MATCH(I8,数据元说明!C:C,0),5) -> 12位人行支付行号或SWIFT行号。 | L8: =INDEX(数据元说明!A:F,MATCH(I8,数据元说明!C:C,0),6) -> C..30 | M8: 需填报人行大小额支付系统中登记的“人行支付行号”；允许多个内部机构号对应同一个“人行支付行号”；该字段不可为空，内设机构、虚拟机构等无“人行支付行号”的，填报本级或上一级机构的“人行支付行号”，优先填本级。
C9: JGXXB | D9: 机构信息表 | E9: 101 | F9: 内部机构号 | G9: 10102 | H9: NBJGH | I9: 内部机构号 | J9: =INDEX(数据元说明!A:F,MATCH(I9,数据元说明!C:C,0),2) -> 001012 | K9: =INDEX(数据元说明!A:F,MATCH(I9,数据元说明!C:C,0),5) -> 银行内部机构号。应具有标识机构的唯一性。 | L9: =INDEX(数据元说明!A:F,MATCH(I9,数据元说明!C:C,0),6) -> C..30 | M9: PK
C10: JGXXB | D10: 机构信息表 | E10: 101 | F10: 金融许可证号 | G10: 10103 | H10: JRXKZH | I10: 金融许可证号 | J10: =INDEX(数据元说明!A:F,MATCH(I10,数据元说明!C:C,0),2) -> 001011 | K10: =INDEX(数据元说明!A:F,MATCH(I10,数据元说明!C:C,0),5) -> 金融许可证机构编码编制规则（试行） 一、机构编码结构 机构编码由大写英文字母和数字组成，共15位。分六个部分，分别是机构类型代码、机构代码、组织类别代码、发证机关代码、地址代码、顺序代码，从左至右顺序排列，如下表所示。 二、机构编码含义 （一）第［一］位是机构类型代码，用大写英文字母表示。 A-政策性银行 B-商业银行 C-农村合作银行 D-城市信用社 E-农村信用社 F-资金互助社 J-金融资产管理公司 K-信托公司 L-财务公司 M-金融租赁公司 N-汽车金融公司 P-货币经纪公司 Q-贷款公司 Z-其他类金融机构 新增机构类型时，根据需要确定机构类型代码。 （二）第［二］位至第［五］位是机构代码，用数字表示。 1.每个法人机构指定唯一的代码，由计算机系统按照规则自动生成。除农村信用社、资金互助社、贷款公司（E、F、Q类机构）外，全国统一编码。E、F、Q类机构在省（自治区、直辖市）范围内统一编码。 2.新设立的机构依照所属机构类型顺序排列。 机构代码编码示例如下： A-政策性银行 0001-国家开发银行 …… B-商业银行 0001-中国工商银行股份有限公司 …… C-农村合作银行 0001-天津大港农村合作银行 …… D-城市信用社 0001-邯郸市城市信用社股份有限公司 …… E-农村信用社天津市 0001-天津市宝坻区农村信用合作联社 …… 新疆维吾尔自治区 0001-新疆维吾尔自治区农村信用社联合社 …… F-资金互助社 吉林省 0001-吉林省梨树县闰家村百信农村资金互助社 …… 青海省 0001-青海省乐都县雨润镇兴乐农村资金互助社 …… J-金融资产管理公司 0001-中国华融资产管理公司 …… K-信托投资公司 0001-中诚信托投资有限责任公司 …… L-财务公司 0001-中海石油财务有限责任公司 …… M-金融租赁公司 0001-中国外贸金融租赁公司 …… N-汽车金融公司 0001-大众汽车金融（中国）有限公司 …… P-货币经纪公司 0001-上海国利货币经纪有限公司 …… Q-贷款公司四川省 0001-四川省仪陇县惠民贷款有限责任公司 …… 新疆维吾尔自治区 0001- …… Z-其他类金融机构 0001-中央国债登记结算有限责任公司 …… （三）第〔六〕位是组织类别代码，用大写英文字母表示。 机构类型不同，组织类别代码的含义不同。定义如下： 1.A-政策性银行 H-总行 G-总行营业部 H-级分行 K-一级分行营业部 M-二级分行 S-支行 X-其他分支机构 2.B-商业银行 H-总行 G-总行营业部、专营机构 B-一级分行 K-一级分行营业部 L-二级分行 M-直属支行 N-二级分行营业部 S-支行 U-分理处、办事处、营业所 V-储蓄所 X-其他分支机构 3.C-农村合作银行 H-总行 S-支行 U-分理处 V-储蓄所 X-其他分支机构 4.D-城市信用社 H-法人 S-分社、营业部 X-其他分支机构 5.E-农村信用社 H-省（自治区、直辖市）联合社 B-地（市）联合社、联社 S-县（市）联合社、联社、合作社（县级） T-信用合作社 U-信用社、分社 V-储蓄所 X-其他分支机构 6.F-资金互助社 H-法人 7.J-金融资产管理公司 H-总公司 B-办事处 X-其他分支机构 8.K-信托公司 H-法人 9.N-汽车金融公司 H-法人 10.L-财务公司 H-总公司 B-分公司 X-其他分支机构 11.M-金融租赁公司 H-总公司 B-分公司 X-其他分支机构 12.P-货币经纪公司 H-总公司 B-分公司 X-其他分支机构 13.Q-贷款公司 H-总公司 B-分公司 X-其他分支机构 14.Z-其他类金融机构 Z类机构组织类别代码编码方法参照以上规则。 新增机构类型时，参照以上规则，根据实际情况定义其组织类别代码。 （四）第〔七〕位是发证机关代码，用数字表示。 1-银保监会 2-银监局 3-银监分局 （五）第〔八〕位至第〔十一〕是地址代码，用数字表示。按照《中华人民共和国行政区划代码》 （GB/T2260），取市（地区、自治州、盟）、直辖市行政区划代码前四位，作为地址代码。 地址代码示例如下：1100表示北京市，1200表示天津市，1301表示石家庄市，…… （六）第〔十二〕位至第〔十五〕位是顺序代码，用数字表示。机构类型代码、机构代码、组织类别代码、发证机关代码和地址代码相同的机构按照制发金融许可证的顺序编码。 三、机构编码的编制规则 编制机构编码时，按照从左至右的顺序依次确定机构类型代码、机构代码、组织类别代码、发证机关代码、地址代码、顺序代码，由计算机自动生成。 为了保证机构编码的唯一性，以利于电子计算机较长时间地存储数据，因行政许可变更需换发金融许可证，涉及机构编码变更的，原机构编码不再使用.金融机构终止的，机构编码不再使用。注销开业许可收回金融许可证的，机构编码不再使用。 | L10: =INDEX(数据元说明!A:F,MATCH(I10,数据元说明!C:C,0),6) -> C..30 | M10: 内设机构、虚拟机构及营业部如有金融许可证的填写金融许可证号，没有金融许可证的取上一级管理机构的金融许可证号。 | N10: 修改 | O10: 备注
C11: JGXXB | D11: 机构信息表 | E11: 101 | F11: 营业执照号 | G11: 10104 | H11: YYZZH | I11: 营业执照号 | J11: =INDEX(数据元说明!A:F,MATCH(I11,数据元说明!C:C,0),2) -> 002012 | K11: =INDEX(数据元说明!A:F,MATCH(I11,数据元说明!C:C,0),5) -> 已登记统一社会信用代码的，填18位统一社会信用代码；未登记统一社会信用代码的，填报营业执照注册号。 | L11: =INDEX(数据元说明!A:F,MATCH(I11,数据元说明!C:C,0),6) -> C..60 | M11: 内设机构、虚拟机构及营业部如有营业执照的填写营业执照号，没有营业执照的取上一级管理机构的营业执照号。 | N11: 修改 | O11: 备注
C12: JGXXB | D12: 机构信息表 | E12: 101 | F12: 银行机构名称 | G12: 10105 | H12: YHJGMC | I12: 名称 | J12: =INDEX(数据元说明!A:F,MATCH(I12,数据元说明!C:C,0),2) -> 001001 | K12: =INDEX(数据元说明!A:F,MATCH(I12,数据元说明!C:C,0),5) -> 名称应与公章所使用的名称完全一致。银行机构以银保监会金融机构许可证登记名称为准。无独立金融机构许可证的机构，可在本名称中体现出机构特征。第三方支付平台填报第三方支付平台名称。 客户名称按照客户的不同类型按如下标准填报。 （1）集团客户，填报银行对该集团授信采用的集团客户名称。视同集团客户填报的供应链融资填报核心企业客户名称。 （2）单一法人客户，经有关部门批准正式使用的全称，与公章所使用的名称完全一致。视同单一法人客户填报的分公司，填报分公司全称，与分公司公章所使用的名称完全一致。客户是境内涉密机构的，客户名称填报为“*********”。 （3）同业客户，经有关部门批准正式使用的客户全称，与客户公章所使用的名称完全一致。 （4）自然人，与有效证件上的姓名一致。 （5）境外客户，客户名称填报英文名称。 | L12: =INDEX(数据元说明!A:F,MATCH(I12,数据元说明!C:C,0),6) -> C..450 | M12: 需填写全称，有金融许可证号的需与金融许可证上的机构名称保持一致。例如：应填报“XX银行股份有限公司XX省分行”，不应填报为“XX省分行”。无独立金融机构许可证的机构，可在本名称中体现出机构特征。 | N12: 修改 | O12: 格式
C13: JGXXB | D13: 机构信息表 | E13: 101 | F13: 机构类别 | G13: 10106 | H13: JGLB | I13: 机构类别 | J13: =INDEX(数据元说明!A:F,MATCH(I13,数据元说明!C:C,0),2) -> 001013 | K13: =INDEX(数据元说明!A:F,MATCH(I13,数据元说明!C:C,0),5) -> 管理机构，营业机构，虚拟机构，内设机构。 | L13: =INDEX(数据元说明!A:F,MATCH(I13,数据元说明!C:C,0),6) -> C..30 | M13: 仅允许填报为：管理机构，营业机构，虚拟机构，内设机构。 各行根据实际情况进行映射： 管理机构：总行、一级分行、专营机构； 营业机构：除总行、一级分行、专营机构以外的有金融许可证的实体机构。专营机构分支机构作为营业机构。营业部也作为营业机构，若无金融许可证号则填报上一级管理机构的金融许可证号； 虚拟机构：具有单独标识、分账核算体系、独立出表的非实体机构，如自由贸易专用账务核算体系（FTU-Free Trade Accounting Unit）； 内设机构：如清算中心等内设部门。 | N13: 修改 | O13: 数据元说明、备注
C14: JGXXB | D14: 机构信息表 | E14: 101 | F14: 行政区划代码 | G14: 10107 | H14: XZQHDM | I14: 地区代码 | J14: =INDEX(数据元说明!A:F,MATCH(I14,数据元说明!C:C,0),2) -> 001028 | K14: =INDEX(数据元说明!A:F,MATCH(I14,数据元说明!C:C,0),5) -> 境内地区参照《GB/T 2260 中华人民共和国行政区划代码》填写国内行政区划代码，填写至二级分类，如110100。境外地区参照《GB/T 2659 世界各国和地区名称代码》定义的三字符代码，如USA。 | L14: =INDEX(数据元说明!A:F,MATCH(I14,数据元说明!C:C,0),6) -> C..6 | M14: 营业机构、管理机构必须填报实际的“行政区划代码”（要求到区县一级，6位代码），内设机构、虚拟机构，营业部取本级或上一级管理机构的行政区划代码，优先取本级。 | N14: 新增
C15: JGXXB | D15: 机构信息表 | E15: 101 | F15: 营业状态 | G15: 10108 | H15: YYZT | I15: 营业状态 | J15: =INDEX(数据元说明!A:F,MATCH(I15,数据元说明!C:C,0),2) -> 001014 | K15: =INDEX(数据元说明!A:F,MATCH(I15,数据元说明!C:C,0),5) -> 营业，停业。 | L15: =INDEX(数据元说明!A:F,MATCH(I15,数据元说明!C:C,0),6) -> C6 | M15: 营业：正常、拟撤销等状态的机构 停业：歇业、筹建中等状态的机构
C16: JGXXB | D16: 机构信息表 | E16: 101 | F16: 成立日期 | G16: 10109 | H16: CLRQ | I16: 日期 | J16: =INDEX(数据元说明!A:F,MATCH(I16,数据元说明!C:C,0),2) -> 001005 | K16: =INDEX(数据元说明!A:F,MATCH(I16,数据元说明!C:C,0),5) -> YYYYMMDD，默认值99991231。 | L16: =INDEX(数据元说明!A:F,MATCH(I16,数据元说明!C:C,0),6) -> C8 | M16: 填报银保监会及其派出机构批复成立的日期 | N16: 修改 | O16: 数据项名称、数据项代码、备注
C17: JGXXB | D17: 机构信息表 | E17: 101 | F17: 机构地址 | G17: 10110 | H17: JGDZ | I17: 地址 | J17: =INDEX(数据元说明!A:F,MATCH(I17,数据元说明!C:C,0),2) -> 001008 | K17: =INDEX(数据元说明!A:F,MATCH(I17,数据元说明!C:C,0),5) -> 中文描述。个人填报个人住址。机构填报有关部门批准的有效证件上登记的地址。参照《企业法人营业执照》中的注册地填报，要写明省（区、市）、地（区、市、州、盟）、县（区、市、旗）。境内涉密机构不填报。客户为境外企业的，填报客户在境外的注册地址（英文）。 | L17: =INDEX(数据元说明!A:F,MATCH(I17,数据元说明!C:C,0),6) -> C..600 | M17: 虚拟机构可为空
C18: JGXXB | D18: 机构信息表 | E18: 101 | F18: 机构联系电话 | G18: 10111 | H18: JGLXDH | I18: 电话 | J18: =INDEX(数据元说明!A:F,MATCH(I18,数据元说明!C:C,0),2) -> 001009 | K18: =INDEX(数据元说明!A:F,MATCH(I18,数据元说明!C:C,0),5) -> 手机号码或者区号-固定电话号码。 | L18: =INDEX(数据元说明!A:F,MATCH(I18,数据元说明!C:C,0),6) -> C..30 | M18: 机构办公联系电话，区号-座机电话，虚拟机构、自助银行及自助设备机构、机构本部和仅承担内部核算职能的机构可为空。非隐私，不做变形。 | N18: 新增
C19: JGXXB | D19: 机构信息表 | E19: 101 | F19: 负责人姓名 | G19: 10112 | H19: FZRXM | I19: 姓名 | J19: =INDEX(数据元说明!A:F,MATCH(I19,数据元说明!C:C,0),2) -> 001016 | K19: =INDEX(数据元说明!A:F,MATCH(I19,数据元说明!C:C,0),5) -> 姓名。 | L19: =INDEX(数据元说明!A:F,MATCH(I19,数据元说明!C:C,0),6) -> C..150 | M19: 非隐私，不做变形。虚拟机构、自助银行及自助设备机构、机构本部和仅承担内部核算职能的机构可为空。
C20: JGXXB | D20: 机构信息表 | E20: 101 | F20: 负责人职务 | G20: 10113 | H20: FZRZW | I20: 职务 | J20: =INDEX(数据元说明!A:F,MATCH(I20,数据元说明!C:C,0),2) -> 001018 | K20: =INDEX(数据元说明!A:F,MATCH(I20,数据元说明!C:C,0),5) -> 中文字典或中文描述，银行自定义。 | L20: =INDEX(数据元说明!A:F,MATCH(I20,数据元说明!C:C,0),6) -> C..150 | M20: 虚拟机构、自助银行及自助设备机构、机构本部和仅承担内部核算职能的机构可为空。
C21: JGXXB | D21: 机构信息表 | E21: 101 | F21: 负责人联系电话 | G21: 10114 | H21: FZRLXDH | I21: 电话 | J21: =INDEX(数据元说明!A:F,MATCH(I21,数据元说明!C:C,0),2) -> 001009 | K21: =INDEX(数据元说明!A:F,MATCH(I21,数据元说明!C:C,0),5) -> 手机号码或者区号-固定电话号码。 | L21: =INDEX(数据元说明!A:F,MATCH(I21,数据元说明!C:C,0),6) -> C..30 | M21: 负责人联系电话，区号-座机电话/手机，虚拟机构、自助银行及自助设备机构、机构本部和仅承担内部核算职能的机构可为空。非隐私，不做变形 | N21: 修改 | O21: 备注
C22: JGXXB | D22: 机构信息表 | E22: 101 | F22: 备注 | G22: 10115 | H22: BBZ | I22: 备注 | J22: =INDEX(数据元说明!A:F,MATCH(I22,数据元说明!C:C,0),2) -> 001038 | K22: =INDEX(数据元说明!A:F,MATCH(I22,数据元说明!C:C,0),5) -> 银行自定义。 | L22: =INDEX(数据元说明!A:F,MATCH(I22,数据元说明!C:C,0),6) -> C..600 | M22: 描述其他字段未能详尽说明的情况，或标注对本条报送记录的特殊说明（如视需要可用于说明各种不满足检核规则的例外情况：客户信息表中可标注“境外客户”“客户已工商注销”“客户名下账户均已管控”，信贷分户账中可标注“线上化业务”“自助类贷款”等）。不同备注事项用英文半角分号隔开。 | N22: 新增
C23: JGXXB | D23: 机构信息表 | E23: 101 | F23: 采集日期 | G23: 10116 | H23: CJRQ | I23: 日期 | J23: =INDEX(数据元说明!A:F,MATCH(I23,数据元说明!C:C,0),2) -> 001005 | K23: =INDEX(数据元说明!A:F,MATCH(I23,数据元说明!C:C,0),5) -> YYYYMMDD，默认值99991231。 | L23: =INDEX(数据元说明!A:F,MATCH(I23,数据元说明!C:C,0),6) -> C8 | M23: PK。采集日期指该期（批次）数据报送的期末日期，例如：按日采集的表，采集日期应为每日；按月采集的表，采集日期应为月末最后一天；以此类推。有特殊报送要求的，应以报送要求的截至日期为采集日期。
C24: YGB | D24: 员工表 | E24: 102 | M24: =INDEX(表结构总览!D:G,MATCH(D24,表结构总览!D:D,0),4) -> 在职类员工需每月报送。员工状态转为离职的，在报送该员工最后状态的次月可不再报送。子公司员工不用报送（理财子公司应报送）。 | N24: 修改 | O24: 备注
C25: YGB | D25: 员工表 | E25: 102 | F25: 金融许可证号 | G25: 10201 | H25: JRXKZH | I25: 金融许可证号 | J25: =INDEX(数据元说明!A:F,MATCH(I25,数据元说明!C:C,0),2) -> 001011 | K25: =INDEX(数据元说明!A:F,MATCH(I25,数据元说明!C:C,0),5) -> 金融许可证机构编码编制规则（试行） 一、机构编码结构 机构编码由大写英文字母和数字组成，共15位。分六个部分，分别是机构类型代码、机构代码、组织类别代码、发证机关代码、地址代码、顺序代码，从左至右顺序排列，如下表所示。 二、机构编码含义 （一）第［一］位是机构类型代码，用大写英文字母表示。 A-政策性银行 B-商业银行 C-农村合作银行 D-城市信用社 E-农村信用社 F-资金互助社 J-金融资产管理公司 K-信托公司 L-财务公司 M-金融租赁公司 N-汽车金融公司 P-货币经纪公司 Q-贷款公司 Z-其他类金融机构 新增机构类型时，根据需要确定机构类型代码。 （二）第［二］位至第［五］位是机构代码，用数字表示。 1.每个法人机构指定唯一的代码，由计算机系统按照规则自动生成。除农村信用社、资金互助社、贷款公司（E、F、Q类机构）外，全国统一编码。E、F、Q类机构在省（自治区、直辖市）范围内统一编码。 2.新设立的机构依照所属机构类型顺序排列。 机构代码编码示例如下： A-政策性银行 0001-国家开发银行 …… B-商业银行 0001-中国工商银行股份有限公司 …… C-农村合作银行 0001-天津大港农村合作银行 …… D-城市信用社 0001-邯郸市城市信用社股份有限公司 …… E-农村信用社天津市 0001-天津市宝坻区农村信用合作联社 …… 新疆维吾尔自治区 0001-新疆维吾尔自治区农村信用社联合社 …… F-资金互助社 吉林省 0001-吉林省梨树县闰家村百信农村资金互助社 …… 青海省 0001-青海省乐都县雨润镇兴乐农村资金互助社 …… J-金融资产管理公司 0001-中国华融资产管理公司 …… K-信托投资公司 0001-中诚信托投资有限责任公司 …… L-财务公司 0001-中海石油财务有限责任公司 …… M-金融租赁公司 0001-中国外贸金融租赁公司 …… N-汽车金融公司 0001-大众汽车金融（中国）有限公司 …… P-货币经纪公司 0001-上海国利货币经纪有限公司 …… Q-贷款公司四川省 0001-四川省仪陇县惠民贷款有限责任公司 …… 新疆维吾尔自治区 0001- …… Z-其他类金融机构 0001-中央国债登记结算有限责任公司 …… （三）第〔六〕位是组织类别代码，用大写英文字母表示。 机构类型不同，组织类别代码的含义不同。定义如下： 1.A-政策性银行 H-总行 G-总行营业部 H-级分行 K-一级分行营业部 M-二级分行 S-支行 X-其他分支机构 2.B-商业银行 H-总行 G-总行营业部、专营机构 B-一级分行 K-一级分行营业部 L-二级分行 M-直属支行 N-二级分行营业部 S-支行 U-分理处、办事处、营业所 V-储蓄所 X-其他分支机构 3.C-农村合作银行 H-总行 S-支行 U-分理处 V-储蓄所 X-其他分支机构 4.D-城市信用社 H-法人 S-分社、营业部 X-其他分支机构 5.E-农村信用社 H-省（自治区、直辖市）联合社 B-地（市）联合社、联社 S-县（市）联合社、联社、合作社（县级） T-信用合作社 U-信用社、分社 V-储蓄所 X-其他分支机构 6.F-资金互助社 H-法人 7.J-金融资产管理公司 H-总公司 B-办事处 X-其他分支机构 8.K-信托公司 H-法人 9.N-汽车金融公司 H-法人 10.L-财务公司 H-总公司 B-分公司 X-其他分支机构 11.M-金融租赁公司 H-总公司 B-分公司 X-其他分支机构 12.P-货币经纪公司 H-总公司 B-分公司 X-其他分支机构 13.Q-贷款公司 H-总公司 B-分公司 X-其他分支机构 14.Z-其他类金融机构 Z类机构组织类别代码编码方法参照以上规则。 新增机构类型时，参照以上规则，根据实际情况定义其组织类别代码。 （四）第〔七〕位是发证机关代码，用数字表示。 1-银保监会 2-银监局 3-银监分局 （五）第〔八〕位至第〔十一〕是地址代码，用数字表示。按照《中华人民共和国行政区划代码》 （GB/T2260），取市（地区、自治州、盟）、直辖市行政区划代码前四位，作为地址代码。 地址代码示例如下：1100表示北京市，1200表示天津市，1301表示石家庄市，…… （六）第〔十二〕位至第〔十五〕位是顺序代码，用数字表示。机构类型代码、机构代码、组织类别代码、发证机关代码和地址代码相同的机构按照制发金融许可证的顺序编码。 三、机构编码的编制规则 编制机构编码时，按照从左至右的顺序依次确定机构类型代码、机构代码、组织类别代码、发证机关代码、地址代码、顺序代码，由计算机自动生成。 为了保证机构编码的唯一性，以利于电子计算机较长时间地存储数据，因行政许可变更需换发金融许可证，涉及机构编码变更的，原机构编码不再使用.金融机构终止的，机构编码不再使用。注销开业许可收回金融许可证的，机构编码不再使用。 | L25: =INDEX(数据元说明!A:F,MATCH(I25,数据元说明!C:C,0),6) -> C..30 | M25: 营业机构、管理机构必须填报“金融许可证号”，内设机构、虚拟机构及营业部取本级或上一级管理机构的金融许可证号，优先取本级。 | N25: 修改 | O25: 备注
C26: YGB | D26: 员工表 | E26: 102 | F26: 内部机构号 | G26: 10202 | H26: NBJGH | I26: 内部机构号 | J26: =INDEX(数据元说明!A:F,MATCH(I26,数据元说明!C:C,0),2) -> 001012 | K26: =INDEX(数据元说明!A:F,MATCH(I26,数据元说明!C:C,0),5) -> 银行内部机构号。应具有标识机构的唯一性。 | L26: =INDEX(数据元说明!A:F,MATCH(I26,数据元说明!C:C,0),6) -> C..30 | M26: 关联数据项：机构信息表.内部机构号。员工如果采集区间发生过更换机构，按采集时点的最后填报内部机构号。 | N26: 修改 | O26: 备注
C27: YGB | D27: 员工表 | E27: 102 | F27: 银行机构名称 | G27: 10203 | H27: YHJGMC | I27: 名称 | J27: =INDEX(数据元说明!A:F,MATCH(I27,数据元说明!C:C,0),2) -> 001001 | K27: =INDEX(数据元说明!A:F,MATCH(I27,数据元说明!C:C,0),5) -> 名称应与公章所使用的名称完全一致。银行机构以银保监会金融机构许可证登记名称为准。无独立金融机构许可证的机构，可在本名称中体现出机构特征。第三方支付平台填报第三方支付平台名称。 客户名称按照客户的不同类型按如下标准填报。 （1）集团客户，填报银行对该集团授信采用的集团客户名称。视同集团客户填报的供应链融资填报核心企业客户名称。 （2）单一法人客户，经有关部门批准正式使用的全称，与公章所使用的名称完全一致。视同单一法人客户填报的分公司，填报分公司全称，与分公司公章所使用的名称完全一致。客户是境内涉密机构的，客户名称填报为“*********”。 （3）同业客户，经有关部门批准正式使用的客户全称，与客户公章所使用的名称完全一致。 （4）自然人，与有效证件上的姓名一致。 （5）境外客户，客户名称填报英文名称。 | L27: =INDEX(数据元说明!A:F,MATCH(I27,数据元说明!C:C,0),6) -> C..450 | M27: 需填写全称，有金融许可证号的需与金融许可证上的机构名称保持一致。关联数据项：机构信息表.银行机构名称 | N27: 修改 | O27: 格式
C28: YGB | D28: 员工表 | E28: 102 | F28: 工号 | G28: 10204 | H28: GH | I28: 工号 | J28: =INDEX(数据元说明!A:F,MATCH(I28,数据元说明!C:C,0),2) -> 001015 | K28: =INDEX(数据元说明!A:F,MATCH(I28,数据元说明!C:C,0),5) -> 工号，银行自定义。 | L28: =INDEX(数据元说明!A:F,MATCH(I28,数据元说明!C:C,0),6) -> C..30 | M28: PK。非员工高管可报送脱敏后的身份证号。 | N28: 修改 | O28: 备注 | P28: 调整数据项位置
C29: YGB | D29: 员工表 | E29: 102 | F29: 姓名 | G29: 10205 | H29: XM | I29: 姓名 | J29: =INDEX(数据元说明!A:F,MATCH(I29,数据元说明!C:C,0),2) -> 001016 | K29: =INDEX(数据元说明!A:F,MATCH(I29,数据元说明!C:C,0),5) -> 姓名。 | L29: =INDEX(数据元说明!A:F,MATCH(I29,数据元说明!C:C,0),6) -> C..150 | M29: 员工姓名为非隐私，不做变形。 | N29: 修改 | O29: 备注
C30: YGB | D30: 员工表 | E30: 102 | F30: 国籍 | G30: 10206 | H30: GJ | I30: 国籍 | J30: =INDEX(数据元说明!A:F,MATCH(I30,数据元说明!C:C,0),2) -> 002004 | K30: =INDEX(数据元说明!A:F,MATCH(I30,数据元说明!C:C,0),5) -> 参照《GB/T 2659-2000 世界各国和地区名称》，填报中文名称。 | L30: =INDEX(数据元说明!A:F,MATCH(I30,数据元说明!C:C,0),6) -> C..60 | M30: 国籍为中国的员工，员工信息需以中文填报。 | N30: 新增
C31: YGB | D31: 员工表 | E31: 102 | F31: 证件类别 | G31: 10207 | H31: ZJLB | I31: 证件类别 | J31: =INDEX(数据元说明!A:F,MATCH(I31,数据元说明!C:C,0),2) -> 002002 | K31: =INDEX(数据元说明!A:F,MATCH(I31,数据元说明!C:C,0),5) -> 同业客户：银行机构代码，金融许可证号，SWIFT编码，其他-XX。 对公客户：统一社会信用代码，组织机构代码，营业执照（工商注册号），公司注册证书，全球法人识别码，其他-XX。 个人客户：居民身份证，军官证，文职干部证，警官证，士兵证，户口簿，临时身份证，其他有效通行旅行证件，护照，学生证，无证件，其他-XX。 无法以枚举类型填报的，以“其他-XX”报送，其中“XX”为银行自定义类型。 对公客户优先填报统一社会信用代码，没有统一社会信用代码的对公客户填报组织机构代码。组织机构代码、统一社会信用代码均没有的可以填报客户提供的批文文号、开户主证件、上级机构统一社会信用代码等，以“其他-XX”填报。 | L31: =INDEX(数据元说明!A:F,MATCH(I31,数据元说明!C:C,0),6) -> C..60
C32: YGB | D32: 员工表 | E32: 102 | F32: 证件号码 | G32: 10208 | H32: ZJHM | I32: 证件号码 | J32: =INDEX(数据元说明!A:F,MATCH(I32,数据元说明!C:C,0),2) -> 002003 | K32: =INDEX(数据元说明!A:F,MATCH(I32,数据元说明!C:C,0),5) -> 与证件类别对应的证件号码。涉及个人身份证件时需按照本规范给定规则进行脱敏处理。 | L32: =INDEX(数据元说明!A:F,MATCH(I32,数据元说明!C:C,0),6) -> C..70 | M32: 隐私，银行机构变形。变形规则见《采集技术接口说明》。 | N32: 修改 | O32: 数据项代码 | P32: 调整数据项位置
C33: YGB | D33: 员工表 | E33: 102 | F33: 联系电话 | G33: 10209 | H33: LXDH | I33: 电话 | J33: =INDEX(数据元说明!A:F,MATCH(I33,数据元说明!C:C,0),2) -> 001009 | K33: =INDEX(数据元说明!A:F,MATCH(I33,数据元说明!C:C,0),5) -> 手机号码或者区号-固定电话号码。 | L33: =INDEX(数据元说明!A:F,MATCH(I33,数据元说明!C:C,0),6) -> C..30 | M33: 非隐私，不做变形。 | N33: 修改 | O33: 备注
C34: YGB | D34: 员工表 | E34: 102 | F34: 所属部门 | G34: 10210 | H34: SSBM | I34: 所属部门 | J34: =INDEX(数据元说明!A:F,MATCH(I34,数据元说明!C:C,0),2) -> 001017 | K34: =INDEX(数据元说明!A:F,MATCH(I34,数据元说明!C:C,0),5) -> 中文字典或中文描述，银行自定义。 | L34: =INDEX(数据元说明!A:F,MATCH(I34,数据元说明!C:C,0),6) -> C..150
C35: YGB | D35: 员工表 | E35: 102 | F35: 岗位编号 | G35: 10211 | H35: GWBH | I35: 岗位编号 | J35: =INDEX(数据元说明!A:F,MATCH(I35,数据元说明!C:C,0),2) -> 001023 | K35: =INDEX(数据元说明!A:F,MATCH(I35,数据元说明!C:C,0),5) -> 银行自定义。 | L35: =INDEX(数据元说明!A:F,MATCH(I35,数据元说明!C:C,0),6) -> C..60 | M35: 同一员工存在多个岗位时，用英文半角分号隔开。 | N35: 修改 | O35: 备注 | P35: 增加备注说明
C36: YGB | D36: 员工表 | E36: 102 | F36: 岗位名称 | G36: 10212 | H36: GWMC | I36: 岗位名称 | J36: =INDEX(数据元说明!A:F,MATCH(I36,数据元说明!C:C,0),2) -> 001025 | K36: =INDEX(数据元说明!A:F,MATCH(I36,数据元说明!C:C,0),5) -> 岗位名称，中文字典或中文描述，银行自定义。 | L36: =INDEX(数据元说明!A:F,MATCH(I36,数据元说明!C:C,0),6) -> C..150 | M36: 同一员工存在多个岗位时，用英文半角分号隔开。 | N36: 新增
C37: YGB | D37: 员工表 | E37: 102 | F37: 是否高管 | G37: 10213 | H37: SFGG | I37: 是否标志 | J37: =INDEX(数据元说明!A:F,MATCH(I37,数据元说明!C:C,0),2) -> 001002 | K37: =INDEX(数据元说明!A:F,MATCH(I37,数据元说明!C:C,0),5) -> 是，否。 | L37: =INDEX(数据元说明!A:F,MATCH(I37,数据元说明!C:C,0),6) -> C3 | M37: 任职资格经银保监会及其派出机构批复的，填写为是。 | N37: 新增
C38: YGB | D38: 员工表 | E38: 102 | F38: 批复日期 | G38: 10214 | H38: PFRQ | I38: 日期 | J38: =INDEX(数据元说明!A:F,MATCH(I38,数据元说明!C:C,0),2) -> 001005 | K38: =INDEX(数据元说明!A:F,MATCH(I38,数据元说明!C:C,0),5) -> YYYYMMDD，默认值99991231。 | L38: =INDEX(数据元说明!A:F,MATCH(I38,数据元说明!C:C,0),6) -> C8 | M38: 任职资格经银保监会及其派出机构批复的必填，其他允许为空。 | N38: 新增
C39: YGB | D39: 员工表 | E39: 102 | F39: 任职日期 | G39: 10215 | H39: RZRQ | I39: 日期 | J39: =INDEX(数据元说明!A:F,MATCH(I39,数据元说明!C:C,0),2) -> 001005 | K39: =INDEX(数据元说明!A:F,MATCH(I39,数据元说明!C:C,0),5) -> YYYYMMDD，默认值99991231。 | L39: =INDEX(数据元说明!A:F,MATCH(I39,数据元说明!C:C,0),6) -> C8 | M39: 任职资格经银保监会及其派出机构批复的必填，其他允许为空。 | N39: 新增
C40: YGB | D40: 员工表 | E40: 102 | F40: 员工类型 | G40: 10216 | H40: YGLX | I40: 员工类型 | J40: =INDEX(数据元说明!A:F,MATCH(I40,数据元说明!C:C,0),2) -> 001033 | K40: =INDEX(数据元说明!A:F,MATCH(I40,数据元说明!C:C,0),5) -> 正式员工，非员工高管，非正式员工，其他-银行自定义。无法以枚举类型填报的，以“其他-XX”填报，其中“XX”为银行自定义类型。 | L40: =INDEX(数据元说明!A:F,MATCH(I40,数据元说明!C:C,0),6) -> C..30 | M40: 正式员工是指与银行业金融机构签订劳动合同的员工。非员工高管是指不是本机构员工的董（理）事会成员、监事会成员、高级管理人员。非正式员工是指银行业金融机构聘用或与劳务派遣机构签订协议从事辅助性金融服务的其他人员。 | N40: 新增 | O40: 数据元、备注 | P40: 增加备注说明
C41: YGB | D41: 员工表 | E41: 102 | F41: 员工状态 | G41: 10217 | H41: YGZT | I41: 员工状态 | J41: =INDEX(数据元说明!A:F,MATCH(I41,数据元说明!C:C,0),2) -> 001034 | K41: =INDEX(数据元说明!A:F,MATCH(I41,数据元说明!C:C,0),5) -> 在岗，离岗，离职，其他-银行自定义。无法以枚举类型填报的，以“其他-XX”填报，其中“XX”为银行自定义类型。 | L41: =INDEX(数据元说明!A:F,MATCH(I41,数据元说明!C:C,0),6) -> C..30 | N41: 修改 | O41: 数据元、备注 | P41: 增加备注说明
C42: YGB | D42: 员工表 | E42: 102 | F42: 备注 | G42: 10218 | H42: BBZ | I42: 备注 | J42: =INDEX(数据元说明!A:F,MATCH(I42,数据元说明!C:C,0),2) -> 001038 | K42: =INDEX(数据元说明!A:F,MATCH(I42,数据元说明!C:C,0),5) -> 银行自定义。 | L42: =INDEX(数据元说明!A:F,MATCH(I42,数据元说明!C:C,0),6) -> C..600 | M42: 描述其他字段未能详尽说明的情况，或标注对本条报送记录的特殊说明（如视需要可用于说明各种不满足检核规则的例外情况：客户信息表中可标注“境外客户”“客户已工商注销”“客户名下账户均已管控”，信贷分户账中可标注“线上化业务”“自助类贷款”等）。不同备注事项用英文半角分号隔开。 | N42: 新增
C43: YGB | D43: 员工表 | E43: 102 | F43: 采集日期 | G43: 10219 | H43: CJRQ | I43: 日期 | J43: =INDEX(数据元说明!A:F,MATCH(I43,数据元说明!C:C,0),2) -> 001005 | K43: =INDEX(数据元说明!A:F,MATCH(I43,数据元说明!C:C,0),5) -> YYYYMMDD，默认值99991231。 | L43: =INDEX(数据元说明!A:F,MATCH(I43,数据元说明!C:C,0),6) -> C8 | M43: PK。采集日期指该期（批次）数据报送的期末日期，例如：按日采集的表，采集日期应为每日；按月采集的表，采集日期应为月末最后一天；以此类推。有特殊报送要求的，应以报送要求的截至日期为采集日期。
...

Sheet 自营报送范围
A1: 自营资金业务报送范围
A3: 业务大类 | B3: 业务中类 | C3: 业务小类
A4: 同业往来 | B4: 买入返售 | C4: 买入返售证券
C5: 买入返售债权
C6: 买入返售信贷资产
C7: 其他-银行自定义
B8: 卖出回购 | C8: 卖出回购证券
C9: 卖出回购债权
C10: 卖出回购信贷资产
C11: 其他-银行自定义
B12: 拆入 | C12: 拆入银行金融机构
C13: 拆入非银行金融机构
B14: 拆出 | C14: 拆出银行金融机构
C15: 拆出非银行金融机构
B16: 同业借款 | C16: 境内同业借款
C17: 境外同业借款
B18: 同业代付 | C18: 代理境内同业付款
C19: 代理境外同业付款
B20: 存放同业 | C20: 非结算性存放同业
B21: 同业存单 | C21: 同业存单发行
C22: 同业存单投资
B23: 债券发行 | C23: 商业银行债
C24: 银行次级债
C25: 银行永续债
C26: 其他-银行自定义
B27: 其他 | C27: 债券借贷
C28: 银行自定义
A29: 债券投资与同业投资 | B29: 债券投资 | C29: 国债
C30: 地方政府债
C31: 央票
C32: 政府支持机构债
C33: 政策性金融债
C34: 商业性金融债
C35: 非金融企业债券
C36: 资产支持证券（信贷资产证券化）
C37: 资产支持证券（交易所资产支持证券）
C38: 资产支持证券（资产支持票据）
C39: 外国债券
C40: 其他-银行自定义
B41: 权益类投资 | C41: 长期股权投资
...

Sheet 即期及衍生品交易信息表填报示例
A1: 示例交易背景 | B1: 填报机构2021年6月1日以6.36元人民币/美元的价格向某交易对手卖出6360元人民币。 | C1: 填报机构2021年12月14日在中国外汇交易中心以1.128美元/欧元的价格向某匿名交易对手卖出500欧元。 | D1: 填报机构2021年12月20日在洲际交易所以1797.4美元/盎司的价格向某交易对手卖出100盎司黄金。 | E1: 某交易对手2021年12月1日以1800美元/盎司的价格向填报机构卖出100盎司账户黄金。 | F1: 填报机构2021年12月14日以365.7元/克的价格向某交易对手卖出4克黄金（积存金）。 | G1: 某交易对手2021年12月14日从其在填报机构开立的黄金（积存金）账户提取100克黄金。 | H1: 某交易对手2021年12月20日以0.5%的利率向填报机构租借5000克黄金，2022年9月15日到期。 | I1: 某交易对手2021年3月29日以15165印尼卢比/美元的价格向填报机构买入本金为4549500印尼卢比的远期合约，2022年3月31日到期。 | J1: 为对冲交易（201）汇率风险，填报机构以15147卢比/美元的价格向其他交易对手买入本金为4544100卢比的远期合约。 | K1: 填报机构2021年12月7日以1857.347美元/盎司的价格向某交易对手购买0.81盎司钯金远期合约，2022年3月9日到期，差额结算。 | L1: 填报机构2021年4月16日以99.43元/张的价格买入20手3年期国开债标准债券远期合约。 | M1: 某交易对手2021年12月7日以19847美元/吨的价格向填报机构买入6吨镍远期合约，2022年3月7日到期。 | N1: 某交易对手2021年11月30日以467.83元人民币/桶的价格向填报机构购买1.8桶账户原油。 | O1: 某交易对手2021年12月24日与填报机构达成名义本金为500万元人民币的远期利率协议，2022年3月24日到期，填报机构收固定利率4.4%、付浮动利率SHIBOR3M。 | Q1: 填报机构2020年4月10日以102.835元/张的价格买入平仓1手五年期国债期货合约 | R1: 填报机构与某交易对手2021年5月25日达成欧元美元掉期交易，填报机构2021年5月27日收1222美元付1000欧元，2021年12月27日收1000欧元付1233美元。 | T1: 某交易对手2021年12月7日与填报机构达成美元白银掉期交易，填报机构2021年12月9日收6729美元、付300盎司白银，2022年1月10日收6729.537美元、付300盎司白银。 | V1: 交易（402）2021年12月15日估值为2812.5美元。 | X1: 填报机构与某交易对手2020年12月15日达成利率互换交易，到期日为2021年12月15日，名义本金均为1000元人民币，每季度最后一个月的15日交换利息，填报机构收浮动利率FR007+50BP、付固定利率2.63%。 | Z1: 填报机构2020年5月21日与某交易对手达成交叉货币互换交易，2020年5月21日填报机构收1000美元本金、付6500元人民币本金，每年3月21日和9月21日互换利息，填报机构付美元固定利率6%、收人民币浮动利率SHIBOR3M+10BP，2022年3月21日完成最后一次利息交换以及本金交换。 | AB1: 某交易对手2019年10月23日以250BP的价格向填报机构买入名义本金为1亿元人民币的某信用风险缓释凭证。 | AC1: 填报机构2019年12月13日以1BP的价格向某交易对手卖出名义本金为1000万元人民币的某公司信用违约互换。 | AD1: 填报机构2021年11月5日向某交易对手买入美元对人民币欧式看涨期权，本金为1000美元，约定汇率为6.59人民币/美元，期权费为20元人民币，2021年11月26日到期。 | AE1: 某交易对手2021年10月15日向填报机构购买名义本金为8000欧元、挂钩EURIBOR3M的利率下限期权，期权费为0，2024年10月29日到期，2021年11月24日起每季度交割，某交易对手有权要求填报机构支付EURIBOR3M小于0的部分。 | AF1: 填报银行2021年3月29日以1BP的价格向某交易对手购买名义本金为1千万元、挂钩FDR001的利率上限期权，按季度交割，填报银行有权要求某交易对手支付FDR001超过1.5%的部分。 | AG1: 某交易对手2021年12月24日以10500元人民币的价格向填报机构买入挂钩LPR1Y、名义本金500万元、上限为4.05%的利率期权，同时以10000元人民币的价格向填报机构卖出挂钩LPR1Y、名义本金500万元、下限为3.8%的利率期权，按季度重置和支付，2022年12月24日到期。 | AI1: 某交易对手2019年4月5日向填报机构买入2200万磅棉花欧式看涨期权，期权费0.017美元/磅，行权日2019年6月21日，行权价格0.81美元/磅。 | AJ1: 交易（505）2019年5月31日估值为370000美元。 | AK1: 某交易对手2021年12月15日向填报机构购买10盎司黄金欧式看跌期权，2022年3月14日到期，期权费为350美元，约定单价为1650美元/盎司。 | AL1: 填报机构2021年12月15日向某交易对手购买名义本金为100美元的二元期权，行权日为2022年3月14日，期权费45美元，行权条件为欧元兑美元汇率大于等于1.135。 | AM1: 某交易对手2021年12月15日向填报机构购买名义本金为150美元的二元期权，期权费78美元，行权条件为2022年3月14日前欧元兑美元汇率小于等于1.15。 | AN1: 填报机构2021年12月15日向某交易对手购买名义本金为500元人民币的二元期权，期权费300元人民币，行权条件为2022年3月14日前欧元兑美元汇率在(1.105,1.16)区间内。 | AO1: 填报机构2021年11月30日在上海黄金交易所以368.66元/克的价格买入9000克AU(T+D)合约。 | AP1: 填报机构2012年6月12日向某交易对手买入利率掉期期权，期权费为200美元，填报机构在期权到期日（2012年9月12日）决定是否进行一笔名义本金为200000美元的利率互换：填报机构付浮动利率USD 3M LIBOR+2%、收固定利率3%。
A2: 金融许可证号 | B2: XXX | C2: XXX | D2: XXX | E2: XXX | F2: XXX | G2: XXX | H2: XXX | I2: XXX | J2: XXX | K2: XXX | L2: XXX | M2: XXX | N2: XXX | O2: XXX | P2: XXX | Q2: XXX | R2: XXX | S2: XXX | T2: XXX | U2: XXX | V2: XXX | W2: XXX | X2: XXX | Y2: XXX | Z2: XXX | AA2: XXX | AB2: XXX | AC2: XXX | AD2: XXX | AE2: XXX | AF2: XXX | AG2: XXX | AH2: XXX | AI2: XXX | AJ2: XXX | AK2: XXX | AL2: XXX | AM2: XXX | AN2: XXX | AO2: XXX | AP2: XXX | AQ2: XXX | AR2: XXX
A3: 内部机构号 | B3: XXX | C3: XXX | D3: XXX | E3: XXX | F3: XXX | G3: XXX | H3: XXX | I3: XXX | J3: XXX | K3: XXX | L3: XXX | M3: XXX | N3: XXX | O3: XXX | P3: XXX | Q3: XXX | R3: XXX | S3: XXX | T3: XXX | U3: XXX | V3: XXX | W3: XXX | X3: XXX | Y3: XXX | Z3: XXX | AA3: XXX | AB3: XXX | AC3: XXX | AD3: XXX | AE3: XXX | AF3: XXX | AG3: XXX | AH3: XXX | AI3: XXX | AJ3: XXX | AK3: XXX | AL3: XXX | AM3: XXX | AN3: XXX | AO3: XXX | AP3: XXX | AQ3: XXX | AR3: XXX
A4: 银行机构名称 | B4: XXX | C4: XXX | D4: XXX | E4: XXX | F4: XXX | G4: XXX | H4: XXX | I4: XXX | J4: XXX | K4: XXX | L4: XXX | M4: XXX | N4: XXX | O4: XXX | P4: XXX | Q4: XXX | R4: XXX | S4: XXX | T4: XXX | U4: XXX | V4: XXX | W4: XXX | X4: XXX | Y4: XXX | Z4: XXX | AA4: XXX | AB4: XXX | AC4: XXX | AD4: XXX | AE4: XXX | AF4: XXX | AG4: XXX | AH4: XXX | AI4: XXX | AJ4: XXX | AK4: XXX | AL4: XXX | AM4: XXX | AN4: XXX | AO4: XXX | AP4: XXX | AQ4: XXX | AR4: XXX
A5: 交易编号 | B5: 101 | C5: 102 | D5: 103 | E5: 104 | F5: 105 | G5: 106 | H5: 107 | I5: 201 | J5: 202 | K5: 203 | L5: 204 | M5: 205 | N5: 206 | O5: 207 | P5: 207 | Q5: 301 | R5: 401 | S5: 401 | T5: 402 | U5: 402 | V5: 402 | W5: 402 | X5: 403 | Y5: 403 | Z5: 404 | AA5: 404 | AB5: 405 | AC5: 406 | AD5: 501 | AE5: 502 | AF5: 503 | AG5: 504 | AH5: 504 | AI5: 505 | AJ5: 505 | AK5: 506 | AL5: 507 | AM5: 508 | AN5: 509 | AO5: 601 | AP5: 701 | AQ5: 701 | AR5: 701
A6: 业务品种 | B6: 即期结售汇 | C6: 即期外汇买卖 | D6: 即期贵金属 | E6: 双向账户贵金属 | F6: 贵金属积存金 | G6: 贵金属积存金提取 | H6: 贵金属租借 | I6: 远期外汇 | J6: 远期外汇 | K6: 远期贵金属 | L6: 标准债券远期 | M6: 商品远期 | N6: 远期账户商品 | O6: 远期利率协议 | Q6: 国债期货 | R6: 外汇掉期 | T6: 贵金属掉期 | V6: 贵金属掉期（估值） | X6: 利率互换 | Z6: 交叉货币互换 | AB6: 信用风险缓释凭证 | AC6: 信用违约互换 | AD6: 外汇期权 | AE6: 利率下限期权 | AF6: 利率上限期权 | AG6: 领式期权 | AI6: 商品期权 | AJ6: 商品期权（估值） | AK6: 贵金属期权 | AL6: 二元期权（digital） | AM6: 二元期权（one touch） | AN6: 二元期权(double no touch) | AO6: AU(T+D) | AP6: 利率掉期期权
A7: 基础资产类型 | B7: 汇率 | C7: 汇率 | D7: 贵金属 | E7: 贵金属 | F7: 贵金属 | G7: 贵金属 | H7: 贵金属 | I7: 汇率 | J7: 汇率 | K7: 贵金属 | L7: 利率 | M7: 商品 | N7: 商品 | O7: 利率 | P7: 利率 | Q7: 利率 | R7: 汇率 | S7: 汇率 | T7: 贵金属 | U7: 贵金属 | V7: 贵金属 | W7: 贵金属 | X7: 利率 | Y7: 利率 | Z7: 利率 | AA7: 利率 | AB7: 信用 | AC7: 信用 | AD7: 汇率 | AE7: 利率 | AF7: 利率 | AG7: 利率 | AH7: 利率 | AI7: 商品 | AJ7: 商品 | AK7: 贵金属 | AL7: 汇率 | AM7: 汇率 | AN7: 汇率 | AO7: 贵金属 | AP7: 利率 | AQ7: 利率 | AR7: 利率
A8: 基础资产名称 | B8: USDCNY | C8: EURUSD | D8: XAU | E8: XAU | F8: 黄金 | G8: 黄金 | H8: 黄金 | I8: USDIDR | J8: USDIDR | K8: XPD | L8: 3年期虚拟国开债 | M8: 镍 | N8: 原油 | O8: 固定利率 | P8: SHIBOR3M | Q8: 5年期虚拟国债 | R8: USD | S8: EUR | T8: USD | U8: XAG | V8: USD | W8: XAG | X8: 固定利率 | Y8: FR007 | Z8: 固定利率 | AA8: SHIBOR3M | AB8: 某信用风险缓释凭证 | AC8: 某公司信用事件 | AD8: USDCNY | AE8: EURIBOR3M | AF8: FDR001 | AG8: LPR1Y | AH8: LPR1Y | AI8: 棉花 | AJ8: 棉花 | AK8: XAUUSD | AL8: EURUSD | AM8: EURUSD | AN8: EURUSD | AO8: 黄金 | AP8: USD 3M LIBOR | AQ8: USD 3M LIBOR | AR8: 固定利率
A9: 交易类型 | B9: 代客 | C9: 做市 | D9: 自营 | E9: 代客 | F9: 自营 | G9: 自营 | H9: 自营 | I9: 代客 | J9: 代客平盘 | K9: 代客 | L9: 做市 | M9: 代客 | N9: 代客 | O9: 代客 | P9: 代客 | Q9: 做市 | R9: 自营 | S9: 自营 | T9: 代客 | U9: 代客 | V9: 代客 | W9: 代客 | X9: 自营 | Y9: 自营 | Z9: 自营 | AA9: 自营 | AB9: 自营 | AC9: 做市 | AD9: 自营 | AE9: 套期保值 | AF9: 做市 | AG9: 代客 | AH9: 代客 | AI9: 做市 | AJ9: 做市 | AK9: 代客 | AL9: 做市 | AM9: 做市 | AN9: 代客 | AO9: 自营 | AP9: 做市 | AQ9: 做市 | AR9: 做市
A10: 合约种类 | B10: 即期 | C10: 即期 | D10: 即期 | E10: 即期 | F10: 即期 | G10: 即期 | H10: 即期 | I10: 远期 | J10: 远期 | K10: 远期 | L10: 远期 | M10: 远期 | N10: 远期 | O10: 远期 | P10: 远期 | Q10: 期货 | R10: 掉期 | S10: 掉期 | T10: 掉期 | U10: 掉期 | V10: 掉期 | W10: 掉期 | X10: 互换 | Y10: 互换 | Z10: 互换 | AA10: 互换 | AB10: 互换 | AC10: 互换 | AD10: 期权 | AE10: 期权 | AF10: 期权 | AG10: 期权 | AH10: 期权 | AI10: 期权 | AJ10: 期权 | AK10: 期权 | AL10: 期权 | AM10: 期权 | AN10: 期权 | AO10: 延期交收 | AP10: 期权 | AQ10: 互换 | AR10: 互换
A11: 交易状态 | B11: 新增 | C11: 新增 | D11: 新增 | E11: 新增 | F11: 新增 | G11: 新增 | H11: 新增 | I11: 新增 | J11: 新增 | K11: 新增 | L11: 新增 | M11: 新增 | N11: 新增 | O11: 新增 | P11: 新增 | Q11: 新增 | R11: 新增 | S11: 新增 | T11: 新增 | U11: 新增 | V11: 估值 | W11: 估值 | X11: 新增 | Y11: 新增 | Z11: 新增 | AA11: 新增 | AB11: 新增 | AC11: 新增 | AD11: 新增 | AE11: 新增 | AF11: 新增 | AG11: 新增 | AH11: 新增 | AI11: 新增 | AJ11: 估值 | AK11: 新增 | AL11: 新增 | AM11: 新增 | AN11: 新增 | AO11: 新增 | AP11: 新增 | AQ11: 新增 | AR11: 新增
A12: 买方名称 | B12: 某交易对手 | D12: 某交易对手 | E12: 填报机构 | F12: 某交易对手 | G12: 某交易对手 | H12: 某交易对手 | I12: 某交易对手 | J12: 填报机构 | K12: 填报机构 | L12: 填报机构 | M12: 某交易对手 | N12: 某交易对手 | O12: 某交易对手 | P12: 填报机构 | Q12: 填报机构 | R12: 某交易对手 | S12: 某交易对手 | T12: 某交易对手 | U12: 某交易对手 | V12: 某交易对手 | W12: 某交易对手 | X12: 填报机构 | Y12: 某交易对手 | Z12: 填报机构 | AA12: 某交易对手 | AB12: 某交易对手 | AC12: 某交易对手 | AD12: 填报机构 | AE12: 某交易对手 | AF12: 填报银行 | AG12: 某交易对手 | AH12: 填报银行 | AI12: 某交易对手 | AJ12: 某交易对手 | AK12: 某交易对手 | AL12: 填报机构 | AM12: 填报机构 | AN12: 某交易对手 | AO12: 填报机构 | AP12: 填报机构 | AQ12: 填报机构 | AR12: 某交易对手
A13: 买方客户统一编号 | B13: XXX | D13: XXX | E13: XXX | F13: XXX | G13: XXX | H13: XXX | I13: XXX | J13: XXX | K13: XXX | L13: XXX | M13: XXX | N13: XXX | O13: XXX | P13: XXX | Q13: XXX | R13: XXX | S13: XXX | T13: XXX | U13: XXX | V13: XXX | W13: XXX | X13: XXX | Y13: XXX | Z13: XXX | AA13: XXX | AB13: XXX | AC13: XXX | AD13: XXX | AE13: XXX | AF13: XXX | AG13: XXX | AH13: XXX | AI13: XXX | AJ13: XXX | AK13: XXX | AL13: XXX | AM13: XXX | AN13: XXX | AO13: XXX | AP13: XXX | AQ13: XXX | AR13: XXX
A14: 卖方名称 | B14: 填报机构 | C14: 填报机构 | D14: 填报机构 | E14: 某交易对手 | F14: 填报机构 | G14: 填报机构 | H14: 填报机构 | I14: 填报机构 | J14: 某交易对手 | K14: 某交易对手 | M14: 填报机构 | N14: 填报机构 | O14: 填报机构 | P14: 某交易对手 | R14: 填报机构 | S14: 填报机构 | T14: 填报机构 | U14: 填报机构 | V14: 填报机构 | W14: 填报机构 | X14: 某交易对手 | Y14: 填报机构 | Z14: 某交易对手 | AA14: 填报机构 | AB14: 填报机构 | AC14: 填报机构 | AD14: 某交易对手 | AE14: 填报机构 | AF14: 某交易对手 | AG14: 填报机构 | AH14: 某交易对手 | AI14: 填报银行 | AJ14: 填报银行 | AK14: 填报机构 | AL14: 某交易对手 | AM14: 某交易对手 | AN14: 填报机构 | AP14: 某交易对手 | AQ14: 某交易对手 | AR14: 填报机构
A15: 卖方客户统一编号 | B15: XXX | C15: XXX | D15: XXX | E15: XXX | F15: XXX | G15: XXX | H15: XXX | I15: XXX | J15: XXX | K15: XXX | M15: XXX | N15: XXX | O15: XXX | P15: XXX | R15: XXX | S15: XXX | T15: XXX | U15: XXX | V15: XXX | W15: XXX | X15: XXX | Y15: XXX | Z15: XXX | AA15: XXX | AB15: XXX | AC15: XXX | AD15: XXX | AE15: XXX | AF15: XXX | AG15: XXX | AH15: XXX | AI15: XXX | AJ15: XXX | AK15: XXX | AL15: XXX | AM15: XXX | AN15: XXX | AP15: XXX | AQ15: XXX | AR15: XXX
A16: 交易日期 | B16: 20210601 | C16: 20211214 | D16: 20211220 | E16: 20211201 | F16: 20211214 | G16: 20211214 | H16: 20211220 | I16: 20210329 | J16: 20210329 | K16: 20211207 | L16: 20210416 | M16: 20211207 | N16: 20211130 | O16: 20211224 | P16: 20211224 | Q16: 20200410 | R16: 20210525 | S16: 20210525 | T16: 20211207 | U16: 20211207 | V16: 20211207 | W16: 20211207 | X16: 20201215 | Y16: 20201215 | Z16: 20200521 | AA16: 20200521 | AB16: 20191023 | AC16: 20191213 | AD16: 20211105 | AE16: 20211015 | AF16: 20210329 | AG16: 20211224 | AH16: 20211224 | AI16: 20190405 | AJ16: 20190405 | AK16: 20211215 | AL16: 20211215 | AM16: 20211215 | AN16: 20211215 | AO16: 20211130 | AP16: 20120612
A17: 交易时间 | B17: 000000 | C17: 000000 | D17: 000000 | E17: 000000 | F17: 000000 | G17: 000000 | H17: 000000 | I17: 000000 | J17: 000000 | K17: 000000 | M17: 000000 | N17: 000000 | O17: 000000 | P17: 000000 | R17: 000000 | S17: 000000 | T17: 000000 | U17: 000000 | V17: 000000 | W17: 000000 | X17: 000000 | Y17: 000000 | Z17: 000000 | AA17: 000000 | AB17: 000000 | AC17: 000000 | AD17: 000000 | AE17: 000000 | AF17: 000000 | AG17: 000000 | AH17: 000000 | AI17: 000000 | AJ17: 000000 | AK17: 000000 | AL17: 000000 | AM17: 000000 | AN17: 000000 | AO17: 000000 | AP17: 000000
A18: 起息日期 | B18: 20210603 | C18: 20211216 | D18: 20211222 | E18: 20211201 | F18: 20211214 | G18: 20211214 | H18: 20211220 | I18: 20220331 | J18: 20220331 | K18: 20220309 | M18: 20220307 | O18: 20220324 | P18: 20220324 | R18: 20210527 | S18: 20211227 | T18: 20211209 | U18: 20220110 | V18: 20211209 | W18: 20220110 | X18: 20201215 | Y18: 20201215 | Z18: 20200521 | AA18: 20200521 | AB18: 20191023 | AC18: 20191216 | AD18: 20211126 | AE18: 20211029 | AF18: 20210329 | AG18: 20220121 | AH18: 20220121 | AK18: 20211217 | AL18: 20211217 | AM18: 20211217 | AN18: 20211217 | AP18: 20120912 | AQ18: 20120612 | AR18: 20120612
A19: 到期日期 | B19: 20210603 | C19: 20211216 | D19: 20211222 | E19: 20211201 | F19: 20211214 | G19: 20211214 | H19: 20220915 | I19: 20220331 | J19: 20220331 | K19: 20220309 | L19: 202106 | M19: 20220307 | N19: 20211230 | O19: 20220324 | P19: 20220324 | Q19: 202009 | R19: 20210527 | S19: 20211227 | T19: 20211209 | U19: 20220110 | V19: 20211209 | W19: 20220110 | X19: 20201215 | Y19: 20201215 | Z19: 20200921 | AA19: 20200921 | AB19: 20221023 | AC19: 20191227 | AD19: 20211126 | AE19: 20211124 | AF19: 20210629 | AG19: 20220121 | AH19: 20220121 | AI19: 20190621 | AJ19: 20190621 | AK19: 20220314 | AL19: 20220314 | AM19: 20220314 | AN19: 20220314 | AP19: 20120912 | AQ19: 20121212 | AR19: 20121212
A20: 截止日期 | B20: 20210603 | C20: 20211216 | D20: 20211222 | E20: 20211201 | F20: 20211214 | G20: 20211214 | H20: 20220915 | I20: 20220331 | J20: 20220331 | K20: 20220309 | L20: 202106 | M20: 20220307 | N20: 20211230 | O20: 20220324 | P20: 20220324 | Q20: 202009 | R20: 20211227 | S20: 20211227 | T20: 20220110 | U20: 20220110 | V20: 20220110 | W20: 20220110 | X20: 20211215 | Y20: 20211215 | Z20: 20220321 | AA20: 20220321 | AB20: 20221023 | AC20: 20191227 | AD20: 20211126 | AE20: 20241029 | AF20: 20220629 | AG20: 20221224 | AH20: 20221224 | AI20: 20190621 | AJ20: 20190621 | AK20: 20220316 | AL20: 20220316 | AM20: 20220316 | AN20: 20220316 | AP20: 20120912 | AQ20: 20121212 | AR20: 20121212
A21: 交割频率 | X21: 3M | Y21: 3M | Z21: 6M | AA21: 6M | AE21: 3M | AF21: 3M | AG21: 3M | AH21: 3M
A22: 标的数量 | B22: 6360 | C22: 500 | D22: 100 | E22: 100 | F22: 4 | G22: 100 | H22: 5000 | I22: 300 | J22: 300 | K22: 0.81 | L22: 1000000 | M22: 6 | N22: 1.8 | O22: 5000000 | P22: 5000000 | Q22: 1000000 | R22: 1000 | S22: 1233 | T22: 300 | U22: 6729.537 | V22: 300 | W22: 6729.537 | X22: 1000 | Y22: 1000 | Z22: 1000 | AA22: 6500 | AB22: 100000000 | AC22: 10000000 | AD22: 6590 | AE22: 8000 | AF22: 10000000 | AG22: 5000000 | AH22: 5000000 | AI22: 22000000 | AJ22: 22000000 | AK22: 10 | AL22: 100 | AM22: 150 | AN22: 500 | AO22: 9000 | AP22: 200000 | AQ22: 200000 | AR22: 200000
A23: 标的数量单位 | B23: CNY | C23: EUR | D23: 盎司 | E23: 盎司 | F23: 克 | G23: 克 | H23: 克 | I23: USD | J23: USD | K23: 盎司 | L23: CNY | M23: 吨 | N23: 桶 | O23: CNY | P23: CNY | Q23: CNY | R23: EUR | S23: USD | T23: 盎司 | U23: USD | V23: 盎司 | W23: USD | X23: CNY | Y23: CNY | Z23: USD | AA23: CNY | AB23: CNY | AC23: CNY | AD23: CNY | AE23: EUR | AF23: CNY | AG23: CNY | AH23: CNY | AI23: 磅 | AJ23: 磅 | AK23: 盎司 | AL23: USD | AM23: USD | AN23: CNY | AO23: 克 | AP23: USD | AQ23: USD | AR23: USD
A24: 成交价格 | B24: 1000 | C24: 564 | D24: 179740 | E24: 180000 | F24: 1462.79 | G24: 100 | H24: 50 | I24: 4549500 | J24: 4544100 | K24: 1504.4511 | L24: 9943000 | M24: 119082 | N24: 842.094 | O24: 440 | P24: 0 | Q24: 1028350 | R24: 1222 | S24: 1000 | T24: 6729 | U24: 300 | V24: 6729 | W24: 300 | X24: 263 | Y24: 50 | Z24: 600 | AA24: 10 | AB24: 250 | AC24: 1 | AD24: 20 | AE24: 0 | AF24: 1000 | AG24: 10500 | AH24: 10000 | AI24: 374000 | AJ24: 374000 | AK24: 350 | AL24: 45 | AM24: 78 | AN24: 300 | AO24: 3317940 | AP24: 200 | AQ24: 200 | AR24: 300
A25: 成交价格单位 | B25: USD | C25: USD | D25: USD | E25: USD | F25: CNY | G25: 克 | H25: BP | I25: IDR | J25: IDR | K25: USD | L25: CNY | M25: USD | N25: CNY | O25: BP | P25: BP | Q25: CNY | R25: USD | S25: EUR | T25: USD | U25: 盎司 | V25: USD | W25: 盎司 | X25: BP | Y25: BP | Z25: BP | AA25: BP | AB25: BP | AC25: BP | AD25: CNY | AE25: EUR | AF25: CNY | AG25: CNY | AH25: CNY | AI25: USD | AJ25: USD | AK25: USD | AL25: USD | AM25: USD | AN25: CNY | AO25: CNY | AP25: USD | AQ25: BP | AR25: BP
A26: 交易场所 | B26: 场外 | C26: 中国外汇交易中心 | D26: Intercontinental Exchange | E26: 场外 | F26: 场外 | G26: 场外 | H26: 上海黄金交易所 | I26: 场外 | J26: 场外 | K26: 场外 | L26: 场外 | M26: 场外 | N26: 场外 | O26: 场外 | P26: 场外 | Q26: 中国金融期货交易所 | R26: 场外 | S26: 场外 | T26: 场外 | U26: 场外 | V26: 场外 | W26: 场外 | X26: 场外 | Y26: 场外 | Z26: 场外 | AA26: 场外 | AB26: 场外 | AC26: 场外 | AD26: 场外 | AE26: 场外 | AF26: 场外 | AG26: 场外 | AH26: 场外 | AI26: 场外 | AJ26: 场外 | AK26: 场外 | AL26: 场外 | AM26: 场外 | AN26: 场外 | AO26: 上海黄金交易所 | AP26: 场外 | AQ26: 场外 | AR26: 场外
A27: 交割方式 | B27: 全额 | C27: 净额 | D27: 全额 | E27: 全额 | F27: 全额 | G27: 全额 | H27: 全额 | I27: 差额 | J27: 差额 | K27: 差额 | L27: 差额 | M27: 全额 | N27: 全额 | O27: 差额 | P27: 差额 | Q27: 全额 | R27: 全额 | S27: 全额 | T27: 全额 | U27: 全额 | V27: 全额 | W27: 全额 | X27: 差额 | Y27: 差额 | Z27: 差额 | AA27: 差额 | AB27: 全额 | AC27: 全额 | AD27: 全额 | AE27: 差额 | AF27: 全额 | AG27: 差额 | AH27: 差额 | AI27: 差额 | AJ27: 差额 | AK27: 差额 | AL27: 差额 | AM27: 差额 | AN27: 差额 | AO27: 全额 | AP27: 差额 | AQ27: 差额 | AR27: 差额
A28: 期权类型 | AD28: 看涨 | AE28: 下限 | AF28: 上限 | AG28: 上限 | AH28: 下限 | AI28: 看涨 | AJ28: 看涨 | AK28: 看跌 | AL28: 看涨 | AM28: 看跌 | AN28: 其他-双边不触碰 | AP28: 看跌
A29: 行权方式 | AD29: 欧式 | AE29: 欧式 | AF29: 欧式 | AG29: 欧式 | AH29: 欧式 | AI29: 欧式 | AJ29: 欧式 | AK29: 欧式 | AL29: 欧式 | AM29: 美式 | AN29: 美式 | AP29: 欧式
A30: 行权价格 | AD30: 1000 | AE30: 0 | AF30: 150 | AG30: 405 | AH30: 380 | AI30: 17820000 | AJ30: 17820000 | AK30: 16500 | AL30: 1.135 | AM30: 1.15 | AP30: 200
A31: 行权价格单位 | AD31: USD | AE31: BP | AF31: BP | AG31: BP | AH31: BP | AI31: USD | AJ31: USD | AK31: USD | AL31: EURUSD | AM31: EURUSD | AP31: BP
A32: 保证金标志 | B32: 否 | C32: 否 | D32: 否 | E32: 是 | F32: 否 | G32: 否 | H32: 否 | I32: 否 | J32: 否 | K32: 是 | L32: 否 | M32: 是 | N32: 是 | O32: 否 | P32: 否 | Q32: 是 | R32: 否 | S32: 否 | T32: 是 | U32: 是 | V32: 是 | W32: 是 | X32: 否 | Y32: 否 | Z32: 否 | AA32: 否 | AB32: 否 | AC32: 否 | AD32: 否 | AE32: 否 | AF32: 否 | AG32: 否 | AH32: 否 | AI32: 否 | AJ32: 否 | AK32: 否 | AL32: 否 | AM32: 否 | AN32: 否 | AO32: 是 | AP32: 否 | AQ32: 否 | AR32: 否
A33: 主协议名称 | I33: ISDA;NAFMII | J33: ISDA;NAFMII | K33: NAFMII | M33: ISDA | R33: NAFMII | S33: NAFMII | T33: ISDA | U33: ISDA | V33: ISDA | W33: ISDA | X33: NAFMII | Y33: NAFMII | Z33: NAFMII | AA33: NAFMII | AB33: NAFMII | AC33: NAFMII | AD33: NAFMII | AF33: NAFMII | AI33: ISDA | AJ33: ISDA | AK33: NAFMII | AL33: ISDA | AM33: ISDA | AN33: NAFMII
A34: 中央交易对手 | C34: 上海清算所 | L34: 上海清算所 | Q34: 中国金融期货交易所
A35: 估值金额 | V35: 2812.5 | W35: 2812.5 | AJ35: 370000
A36: 估值币种 | V36: USD | W36: USD | AJ36: USD
A37: 估值日期 | V37: 20211215 | W37: 20211215 | AJ37: 20190531
A38: 交易员工号 | B38: XXX | C38: XXX | D38: XXX | E38: XXX | F38: XXX | G38: XXX | H38: XXX | I38: XXX | J38: XXX | K38: XXX | L38: XXX | M38: XXX | N38: XXX | O38: XXX | P38: XXX | Q38: XXX | R38: XXX | S38: XXX | T38: XXX | U38: XXX | V38: XXX | W38: XXX | X38: XXX | Y38: XXX | Z38: XXX | AA38: XXX | AB38: XXX | AC38: XXX | AD38: XXX | AE38: XXX | AF38: XXX | AG38: XXX | AH38: XXX | AI38: XXX | AJ38: XXX | AK38: XXX | AL38: XXX | AM38: XXX | AN38: XXX | AO38: XXX | AP38: XXX | AQ38: XXX | AR38: XXX
A39: 审批人工号 | B39: XXX | C39: XXX | D39: XXX | E39: XXX | F39: XXX | G39: XXX | H39: XXX | I39: XXX | J39: XXX | K39: XXX | L39: XXX | M39: XXX | N39: XXX | O39: XXX | P39: XXX | Q39: XXX | R39: XXX | S39: XXX | T39: XXX | U39: XXX | V39: XXX | W39: XXX | X39: XXX | Y39: XXX | Z39: XXX | AA39: XXX | AB39: XXX | AC39: XXX | AD39: XXX | AE39: XXX | AF39: XXX | AG39: XXX | AH39: XXX | AI39: XXX | AJ39: XXX | AK39: XXX | AL39: XXX | AM39: XXX | AN39: XXX | AO39: XXX | AP39: XXX | AQ39: XXX | AR39: XXX
A40: 备注 | B40: XXX | C40: XXX | D40: XXX | E40: XXX | F40: XXX | G40: XXX | H40: XXX | I40: XXX | J40: XXX | K40: XXX | L40: XXX | M40: XXX | N40: XXX | O40: XXX | P40: XXX | Q40: XXX | R40: XXX | S40: XXX | T40: XXX | U40: XXX | V40: XXX | W40: XXX | X40: XXX | Y40: XXX | Z40: XXX | AA40: XXX | AB40: XXX | AC40: XXX | AD40: XXX | AE40: XXX | AF40: XXX | AG40: XXX | AH40: XXX | AI40: XXX | AJ40: XXX | AK40: XXX | AL40: XXX | AM40: XXX | AN40: 1.105,1.16 | AO40: XXX | AP40: XXX | AQ40: XXX | AR40: XXX
...
